2024-11-05 16:14:46,724 - INFO - Server started, log file: ./logs/2024-11-05_16-14-46.log
2024-11-05 16:14:46,730 - INFO - [31m[1mWARNING: This is a development server. Do not use it in a production deployment. Use a production WSGI server instead.[0m
 * Running on all addresses (0.0.0.0)
 * Running on http://127.0.0.1:8000
 * Running on http://10.21.16.131:8000
2024-11-05 16:14:46,730 - INFO - [33mPress CTRL+C to quit[0m
2024-11-05 16:14:51,376 - INFO - Error page accessed
2024-11-05 16:14:51,384 - ERROR - Exception on /error [GET]
Traceback (most recent call last):
  File "/Users/julianfichtinger/Library/CloudStorage/OneDrive-HTLWien3Rennweg/4. Jahr/1. Semester/ITP/Heatseekers/.venv/lib/python3.13/site-packages/flask/app.py", line 880, in full_dispatch_request
    rv = self.dispatch_request()
  File "/Users/julianfichtinger/Library/CloudStorage/OneDrive-HTLWien3Rennweg/4. Jahr/1. Semester/ITP/Heatseekers/.venv/lib/python3.13/site-packages/flask/app.py", line 865, in dispatch_request
    return self.ensure_sync(self.view_functions[rule.endpoint])(**view_args)  # type: ignore[no-any-return]
           ~~~~~~~~~~~~~~~~~~~~~~~~~~~~~~~~~~~~~~~~~~~~~~~~~~~~^^^^^^^^^^^^^
  File "/Users/julianfichtinger/Library/CloudStorage/OneDrive-HTLWien3Rennweg/4. Jahr/1. Semester/ITP/Heatseekers/server.py", line 55, in error
    return render_template_string(functions.read_file("templates/ErrorPage.html"))
  File "/Users/julianfichtinger/Library/CloudStorage/OneDrive-HTLWien3Rennweg/4. Jahr/1. Semester/ITP/Heatseekers/.venv/lib/python3.13/site-packages/flask/templating.py", line 162, in render_template_string
    return _render(app, template, context)
  File "/Users/julianfichtinger/Library/CloudStorage/OneDrive-HTLWien3Rennweg/4. Jahr/1. Semester/ITP/Heatseekers/.venv/lib/python3.13/site-packages/flask/templating.py", line 131, in _render
    rv = template.render(context)
  File "/Users/julianfichtinger/Library/CloudStorage/OneDrive-HTLWien3Rennweg/4. Jahr/1. Semester/ITP/Heatseekers/.venv/lib/python3.13/site-packages/jinja2/environment.py", line 1304, in render
    self.environment.handle_exception()
    ~~~~~~~~~~~~~~~~~~~~~~~~~~~~~~~~~^^
  File "/Users/julianfichtinger/Library/CloudStorage/OneDrive-HTLWien3Rennweg/4. Jahr/1. Semester/ITP/Heatseekers/.venv/lib/python3.13/site-packages/jinja2/environment.py", line 939, in handle_exception
    raise rewrite_traceback_stack(source=source)
  File "<template>", line 20, in top-level template code
  File "/Users/julianfichtinger/Library/CloudStorage/OneDrive-HTLWien3Rennweg/4. Jahr/1. Semester/ITP/Heatseekers/.venv/lib/python3.13/site-packages/flask/app.py", line 1084, in url_for
    return self.handle_url_build_error(error, endpoint, values)
           ~~~~~~~~~~~~~~~~~~~~~~~~~~~^^^^^^^^^^^^^^^^^^^^^^^^^
  File "/Users/julianfichtinger/Library/CloudStorage/OneDrive-HTLWien3Rennweg/4. Jahr/1. Semester/ITP/Heatseekers/.venv/lib/python3.13/site-packages/flask/app.py", line 1073, in url_for
    rv = url_adapter.build(  # type: ignore[union-attr]
        endpoint,
    ...<3 lines>...
        force_external=_external,
    )
  File "/Users/julianfichtinger/Library/CloudStorage/OneDrive-HTLWien3Rennweg/4. Jahr/1. Semester/ITP/Heatseekers/.venv/lib/python3.13/site-packages/werkzeug/routing/map.py", line 924, in build
    raise BuildError(endpoint, values, method, self)
werkzeug.routing.exceptions.BuildError: Could not build url for endpoint 'home'. Did you mean 'view' instead?

During handling of the above exception, another exception occurred:

Traceback (most recent call last):
  File "/Users/julianfichtinger/Library/CloudStorage/OneDrive-HTLWien3Rennweg/4. Jahr/1. Semester/ITP/Heatseekers/.venv/lib/python3.13/site-packages/flask/app.py", line 1473, in wsgi_app
    response = self.full_dispatch_request()
  File "/Users/julianfichtinger/Library/CloudStorage/OneDrive-HTLWien3Rennweg/4. Jahr/1. Semester/ITP/Heatseekers/.venv/lib/python3.13/site-packages/flask/app.py", line 882, in full_dispatch_request
    rv = self.handle_user_exception(e)
  File "/Users/julianfichtinger/Library/CloudStorage/OneDrive-HTLWien3Rennweg/4. Jahr/1. Semester/ITP/Heatseekers/.venv/lib/python3.13/site-packages/flask/app.py", line 772, in handle_user_exception
    return self.ensure_sync(handler)(e)  # type: ignore[no-any-return]
           ~~~~~~~~~~~~~~~~~~~~~~~~~^^^
TypeError: errorhandler() takes 0 positional arguments but 1 was given
2024-11-05 16:14:51,392 - INFO - 127.0.0.1 - - [05/Nov/2024 16:14:51] "[35m[1mGET /error HTTP/1.1[0m" 500 -
2024-11-05 16:14:51,408 - ERROR - Error on request:
Traceback (most recent call last):
  File "/Users/julianfichtinger/Library/CloudStorage/OneDrive-HTLWien3Rennweg/4. Jahr/1. Semester/ITP/Heatseekers/.venv/lib/python3.13/site-packages/flask/app.py", line 880, in full_dispatch_request
    rv = self.dispatch_request()
  File "/Users/julianfichtinger/Library/CloudStorage/OneDrive-HTLWien3Rennweg/4. Jahr/1. Semester/ITP/Heatseekers/.venv/lib/python3.13/site-packages/flask/app.py", line 865, in dispatch_request
    return self.ensure_sync(self.view_functions[rule.endpoint])(**view_args)  # type: ignore[no-any-return]
           ~~~~~~~~~~~~~~~~~~~~~~~~~~~~~~~~~~~~~~~~~~~~~~~~~~~~^^^^^^^^^^^^^
  File "/Users/julianfichtinger/Library/CloudStorage/OneDrive-HTLWien3Rennweg/4. Jahr/1. Semester/ITP/Heatseekers/server.py", line 55, in error
    return render_template_string(functions.read_file("templates/ErrorPage.html"))
  File "/Users/julianfichtinger/Library/CloudStorage/OneDrive-HTLWien3Rennweg/4. Jahr/1. Semester/ITP/Heatseekers/.venv/lib/python3.13/site-packages/flask/templating.py", line 162, in render_template_string
    return _render(app, template, context)
  File "/Users/julianfichtinger/Library/CloudStorage/OneDrive-HTLWien3Rennweg/4. Jahr/1. Semester/ITP/Heatseekers/.venv/lib/python3.13/site-packages/flask/templating.py", line 131, in _render
    rv = template.render(context)
  File "/Users/julianfichtinger/Library/CloudStorage/OneDrive-HTLWien3Rennweg/4. Jahr/1. Semester/ITP/Heatseekers/.venv/lib/python3.13/site-packages/jinja2/environment.py", line 1304, in render
    self.environment.handle_exception()
    ~~~~~~~~~~~~~~~~~~~~~~~~~~~~~~~~~^^
  File "/Users/julianfichtinger/Library/CloudStorage/OneDrive-HTLWien3Rennweg/4. Jahr/1. Semester/ITP/Heatseekers/.venv/lib/python3.13/site-packages/jinja2/environment.py", line 939, in handle_exception
    raise rewrite_traceback_stack(source=source)
  File "<template>", line 20, in top-level template code
  File "/Users/julianfichtinger/Library/CloudStorage/OneDrive-HTLWien3Rennweg/4. Jahr/1. Semester/ITP/Heatseekers/.venv/lib/python3.13/site-packages/flask/app.py", line 1084, in url_for
    return self.handle_url_build_error(error, endpoint, values)
           ~~~~~~~~~~~~~~~~~~~~~~~~~~~^^^^^^^^^^^^^^^^^^^^^^^^^
  File "/Users/julianfichtinger/Library/CloudStorage/OneDrive-HTLWien3Rennweg/4. Jahr/1. Semester/ITP/Heatseekers/.venv/lib/python3.13/site-packages/flask/app.py", line 1073, in url_for
    rv = url_adapter.build(  # type: ignore[union-attr]
    
  File "/Users/julianfichtinger/Library/CloudStorage/OneDrive-HTLWien3Rennweg/4. Jahr/1. Semester/ITP/Heatseekers/.venv/lib/python3.13/site-packages/werkzeug/routing/map.py", line 924, in build
    raise BuildError(endpoint, values, method, self)
werkzeug.routing.exceptions.BuildError: Could not build url for endpoint 'home'. Did you mean 'view' instead?

During handling of the above exception, another exception occurred:

Traceback (most recent call last):
  File "/Users/julianfichtinger/Library/CloudStorage/OneDrive-HTLWien3Rennweg/4. Jahr/1. Semester/ITP/Heatseekers/.venv/lib/python3.13/site-packages/flask/app.py", line 1473, in wsgi_app
    response = self.full_dispatch_request()
  File "/Users/julianfichtinger/Library/CloudStorage/OneDrive-HTLWien3Rennweg/4. Jahr/1. Semester/ITP/Heatseekers/.venv/lib/python3.13/site-packages/flask/app.py", line 882, in full_dispatch_request
    rv = self.handle_user_exception(e)
  File "/Users/julianfichtinger/Library/CloudStorage/OneDrive-HTLWien3Rennweg/4. Jahr/1. Semester/ITP/Heatseekers/.venv/lib/python3.13/site-packages/flask/app.py", line 772, in handle_user_exception
    return self.ensure_sync(handler)(e)  # type: ignore[no-any-return]
           ~~~~~~~~~~~~~~~~~~~~~~~~~^^^
TypeError: errorhandler() takes 0 positional arguments but 1 was given

During handling of the above exception, another exception occurred:

Traceback (most recent call last):
  File "/Users/julianfichtinger/Library/CloudStorage/OneDrive-HTLWien3Rennweg/4. Jahr/1. Semester/ITP/Heatseekers/.venv/lib/python3.13/site-packages/werkzeug/serving.py", line 370, in run_wsgi
    execute(self.server.app)
    ~~~~~~~^^^^^^^^^^^^^^^^^
  File "/Users/julianfichtinger/Library/CloudStorage/OneDrive-HTLWien3Rennweg/4. Jahr/1. Semester/ITP/Heatseekers/.venv/lib/python3.13/site-packages/werkzeug/serving.py", line 331, in execute
    application_iter = app(environ, start_response)
  File "/Users/julianfichtinger/Library/CloudStorage/OneDrive-HTLWien3Rennweg/4. Jahr/1. Semester/ITP/Heatseekers/.venv/lib/python3.13/site-packages/flask/app.py", line 1498, in __call__
    return self.wsgi_app(environ, start_response)
           ~~~~~~~~~~~~~^^^^^^^^^^^^^^^^^^^^^^^^^
  File "/Users/julianfichtinger/Library/CloudStorage/OneDrive-HTLWien3Rennweg/4. Jahr/1. Semester/ITP/Heatseekers/.venv/lib/python3.13/site-packages/flask/app.py", line 1476, in wsgi_app
    response = self.handle_exception(e)
  File "/Users/julianfichtinger/Library/CloudStorage/OneDrive-HTLWien3Rennweg/4. Jahr/1. Semester/ITP/Heatseekers/.venv/lib/python3.13/site-packages/flask/app.py", line 823, in handle_exception
    server_error = self.ensure_sync(handler)(server_error)
TypeError: errorhandler() takes 0 positional arguments but 1 was given
2024-11-05 16:15:00,500 - INFO - Error page accessed
2024-11-05 16:15:00,503 - ERROR - Exception on /error [GET]
Traceback (most recent call last):
  File "/Users/julianfichtinger/Library/CloudStorage/OneDrive-HTLWien3Rennweg/4. Jahr/1. Semester/ITP/Heatseekers/.venv/lib/python3.13/site-packages/flask/app.py", line 880, in full_dispatch_request
    rv = self.dispatch_request()
  File "/Users/julianfichtinger/Library/CloudStorage/OneDrive-HTLWien3Rennweg/4. Jahr/1. Semester/ITP/Heatseekers/.venv/lib/python3.13/site-packages/flask/app.py", line 865, in dispatch_request
    return self.ensure_sync(self.view_functions[rule.endpoint])(**view_args)  # type: ignore[no-any-return]
           ~~~~~~~~~~~~~~~~~~~~~~~~~~~~~~~~~~~~~~~~~~~~~~~~~~~~^^^^^^^^^^^^^
  File "/Users/julianfichtinger/Library/CloudStorage/OneDrive-HTLWien3Rennweg/4. Jahr/1. Semester/ITP/Heatseekers/server.py", line 55, in error
    return render_template_string(functions.read_file("templates/ErrorPage.html"))
  File "/Users/julianfichtinger/Library/CloudStorage/OneDrive-HTLWien3Rennweg/4. Jahr/1. Semester/ITP/Heatseekers/.venv/lib/python3.13/site-packages/flask/templating.py", line 162, in render_template_string
    return _render(app, template, context)
  File "/Users/julianfichtinger/Library/CloudStorage/OneDrive-HTLWien3Rennweg/4. Jahr/1. Semester/ITP/Heatseekers/.venv/lib/python3.13/site-packages/flask/templating.py", line 131, in _render
    rv = template.render(context)
  File "/Users/julianfichtinger/Library/CloudStorage/OneDrive-HTLWien3Rennweg/4. Jahr/1. Semester/ITP/Heatseekers/.venv/lib/python3.13/site-packages/jinja2/environment.py", line 1304, in render
    self.environment.handle_exception()
    ~~~~~~~~~~~~~~~~~~~~~~~~~~~~~~~~~^^
  File "/Users/julianfichtinger/Library/CloudStorage/OneDrive-HTLWien3Rennweg/4. Jahr/1. Semester/ITP/Heatseekers/.venv/lib/python3.13/site-packages/jinja2/environment.py", line 939, in handle_exception
    raise rewrite_traceback_stack(source=source)
  File "<template>", line 20, in top-level template code
  File "/Users/julianfichtinger/Library/CloudStorage/OneDrive-HTLWien3Rennweg/4. Jahr/1. Semester/ITP/Heatseekers/.venv/lib/python3.13/site-packages/flask/app.py", line 1084, in url_for
    return self.handle_url_build_error(error, endpoint, values)
           ~~~~~~~~~~~~~~~~~~~~~~~~~~~^^^^^^^^^^^^^^^^^^^^^^^^^
  File "/Users/julianfichtinger/Library/CloudStorage/OneDrive-HTLWien3Rennweg/4. Jahr/1. Semester/ITP/Heatseekers/.venv/lib/python3.13/site-packages/flask/app.py", line 1073, in url_for
    rv = url_adapter.build(  # type: ignore[union-attr]
        endpoint,
    ...<3 lines>...
        force_external=_external,
    )
  File "/Users/julianfichtinger/Library/CloudStorage/OneDrive-HTLWien3Rennweg/4. Jahr/1. Semester/ITP/Heatseekers/.venv/lib/python3.13/site-packages/werkzeug/routing/map.py", line 924, in build
    raise BuildError(endpoint, values, method, self)
werkzeug.routing.exceptions.BuildError: Could not build url for endpoint 'home'. Did you mean 'view' instead?

During handling of the above exception, another exception occurred:

Traceback (most recent call last):
  File "/Users/julianfichtinger/Library/CloudStorage/OneDrive-HTLWien3Rennweg/4. Jahr/1. Semester/ITP/Heatseekers/.venv/lib/python3.13/site-packages/flask/app.py", line 1473, in wsgi_app
    response = self.full_dispatch_request()
  File "/Users/julianfichtinger/Library/CloudStorage/OneDrive-HTLWien3Rennweg/4. Jahr/1. Semester/ITP/Heatseekers/.venv/lib/python3.13/site-packages/flask/app.py", line 882, in full_dispatch_request
    rv = self.handle_user_exception(e)
  File "/Users/julianfichtinger/Library/CloudStorage/OneDrive-HTLWien3Rennweg/4. Jahr/1. Semester/ITP/Heatseekers/.venv/lib/python3.13/site-packages/flask/app.py", line 772, in handle_user_exception
    return self.ensure_sync(handler)(e)  # type: ignore[no-any-return]
           ~~~~~~~~~~~~~~~~~~~~~~~~~^^^
TypeError: errorhandler() takes 0 positional arguments but 1 was given
2024-11-05 16:15:00,505 - INFO - 127.0.0.1 - - [05/Nov/2024 16:15:00] "[35m[1mGET /error HTTP/1.1[0m" 500 -
2024-11-05 16:15:00,508 - ERROR - Error on request:
Traceback (most recent call last):
  File "/Users/julianfichtinger/Library/CloudStorage/OneDrive-HTLWien3Rennweg/4. Jahr/1. Semester/ITP/Heatseekers/.venv/lib/python3.13/site-packages/flask/app.py", line 880, in full_dispatch_request
    rv = self.dispatch_request()
  File "/Users/julianfichtinger/Library/CloudStorage/OneDrive-HTLWien3Rennweg/4. Jahr/1. Semester/ITP/Heatseekers/.venv/lib/python3.13/site-packages/flask/app.py", line 865, in dispatch_request
    return self.ensure_sync(self.view_functions[rule.endpoint])(**view_args)  # type: ignore[no-any-return]
           ~~~~~~~~~~~~~~~~~~~~~~~~~~~~~~~~~~~~~~~~~~~~~~~~~~~~^^^^^^^^^^^^^
  File "/Users/julianfichtinger/Library/CloudStorage/OneDrive-HTLWien3Rennweg/4. Jahr/1. Semester/ITP/Heatseekers/server.py", line 55, in error
    return render_template_string(functions.read_file("templates/ErrorPage.html"))
  File "/Users/julianfichtinger/Library/CloudStorage/OneDrive-HTLWien3Rennweg/4. Jahr/1. Semester/ITP/Heatseekers/.venv/lib/python3.13/site-packages/flask/templating.py", line 162, in render_template_string
    return _render(app, template, context)
  File "/Users/julianfichtinger/Library/CloudStorage/OneDrive-HTLWien3Rennweg/4. Jahr/1. Semester/ITP/Heatseekers/.venv/lib/python3.13/site-packages/flask/templating.py", line 131, in _render
    rv = template.render(context)
  File "/Users/julianfichtinger/Library/CloudStorage/OneDrive-HTLWien3Rennweg/4. Jahr/1. Semester/ITP/Heatseekers/.venv/lib/python3.13/site-packages/jinja2/environment.py", line 1304, in render
    self.environment.handle_exception()
    ~~~~~~~~~~~~~~~~~~~~~~~~~~~~~~~~~^^
  File "/Users/julianfichtinger/Library/CloudStorage/OneDrive-HTLWien3Rennweg/4. Jahr/1. Semester/ITP/Heatseekers/.venv/lib/python3.13/site-packages/jinja2/environment.py", line 939, in handle_exception
    raise rewrite_traceback_stack(source=source)
  File "<template>", line 20, in top-level template code
  File "/Users/julianfichtinger/Library/CloudStorage/OneDrive-HTLWien3Rennweg/4. Jahr/1. Semester/ITP/Heatseekers/.venv/lib/python3.13/site-packages/flask/app.py", line 1084, in url_for
    return self.handle_url_build_error(error, endpoint, values)
           ~~~~~~~~~~~~~~~~~~~~~~~~~~~^^^^^^^^^^^^^^^^^^^^^^^^^
  File "/Users/julianfichtinger/Library/CloudStorage/OneDrive-HTLWien3Rennweg/4. Jahr/1. Semester/ITP/Heatseekers/.venv/lib/python3.13/site-packages/flask/app.py", line 1073, in url_for
    rv = url_adapter.build(  # type: ignore[union-attr]
    
  File "/Users/julianfichtinger/Library/CloudStorage/OneDrive-HTLWien3Rennweg/4. Jahr/1. Semester/ITP/Heatseekers/.venv/lib/python3.13/site-packages/werkzeug/routing/map.py", line 924, in build
    raise BuildError(endpoint, values, method, self)
werkzeug.routing.exceptions.BuildError: Could not build url for endpoint 'home'. Did you mean 'view' instead?

During handling of the above exception, another exception occurred:

Traceback (most recent call last):
  File "/Users/julianfichtinger/Library/CloudStorage/OneDrive-HTLWien3Rennweg/4. Jahr/1. Semester/ITP/Heatseekers/.venv/lib/python3.13/site-packages/flask/app.py", line 1473, in wsgi_app
    response = self.full_dispatch_request()
  File "/Users/julianfichtinger/Library/CloudStorage/OneDrive-HTLWien3Rennweg/4. Jahr/1. Semester/ITP/Heatseekers/.venv/lib/python3.13/site-packages/flask/app.py", line 882, in full_dispatch_request
    rv = self.handle_user_exception(e)
  File "/Users/julianfichtinger/Library/CloudStorage/OneDrive-HTLWien3Rennweg/4. Jahr/1. Semester/ITP/Heatseekers/.venv/lib/python3.13/site-packages/flask/app.py", line 772, in handle_user_exception
    return self.ensure_sync(handler)(e)  # type: ignore[no-any-return]
           ~~~~~~~~~~~~~~~~~~~~~~~~~^^^
TypeError: errorhandler() takes 0 positional arguments but 1 was given

During handling of the above exception, another exception occurred:

Traceback (most recent call last):
  File "/Users/julianfichtinger/Library/CloudStorage/OneDrive-HTLWien3Rennweg/4. Jahr/1. Semester/ITP/Heatseekers/.venv/lib/python3.13/site-packages/werkzeug/serving.py", line 370, in run_wsgi
    execute(self.server.app)
    ~~~~~~~^^^^^^^^^^^^^^^^^
  File "/Users/julianfichtinger/Library/CloudStorage/OneDrive-HTLWien3Rennweg/4. Jahr/1. Semester/ITP/Heatseekers/.venv/lib/python3.13/site-packages/werkzeug/serving.py", line 331, in execute
    application_iter = app(environ, start_response)
  File "/Users/julianfichtinger/Library/CloudStorage/OneDrive-HTLWien3Rennweg/4. Jahr/1. Semester/ITP/Heatseekers/.venv/lib/python3.13/site-packages/flask/app.py", line 1498, in __call__
    return self.wsgi_app(environ, start_response)
           ~~~~~~~~~~~~~^^^^^^^^^^^^^^^^^^^^^^^^^
  File "/Users/julianfichtinger/Library/CloudStorage/OneDrive-HTLWien3Rennweg/4. Jahr/1. Semester/ITP/Heatseekers/.venv/lib/python3.13/site-packages/flask/app.py", line 1476, in wsgi_app
    response = self.handle_exception(e)
  File "/Users/julianfichtinger/Library/CloudStorage/OneDrive-HTLWien3Rennweg/4. Jahr/1. Semester/ITP/Heatseekers/.venv/lib/python3.13/site-packages/flask/app.py", line 823, in handle_exception
    server_error = self.ensure_sync(handler)(server_error)
TypeError: errorhandler() takes 0 positional arguments but 1 was given
2024-11-05 16:15:00,751 - INFO - Error page accessed
2024-11-05 16:15:00,752 - ERROR - Exception on /error [GET]
Traceback (most recent call last):
  File "/Users/julianfichtinger/Library/CloudStorage/OneDrive-HTLWien3Rennweg/4. Jahr/1. Semester/ITP/Heatseekers/.venv/lib/python3.13/site-packages/flask/app.py", line 880, in full_dispatch_request
    rv = self.dispatch_request()
  File "/Users/julianfichtinger/Library/CloudStorage/OneDrive-HTLWien3Rennweg/4. Jahr/1. Semester/ITP/Heatseekers/.venv/lib/python3.13/site-packages/flask/app.py", line 865, in dispatch_request
    return self.ensure_sync(self.view_functions[rule.endpoint])(**view_args)  # type: ignore[no-any-return]
           ~~~~~~~~~~~~~~~~~~~~~~~~~~~~~~~~~~~~~~~~~~~~~~~~~~~~^^^^^^^^^^^^^
  File "/Users/julianfichtinger/Library/CloudStorage/OneDrive-HTLWien3Rennweg/4. Jahr/1. Semester/ITP/Heatseekers/server.py", line 55, in error
    return render_template_string(functions.read_file("templates/ErrorPage.html"))
  File "/Users/julianfichtinger/Library/CloudStorage/OneDrive-HTLWien3Rennweg/4. Jahr/1. Semester/ITP/Heatseekers/.venv/lib/python3.13/site-packages/flask/templating.py", line 162, in render_template_string
    return _render(app, template, context)
  File "/Users/julianfichtinger/Library/CloudStorage/OneDrive-HTLWien3Rennweg/4. Jahr/1. Semester/ITP/Heatseekers/.venv/lib/python3.13/site-packages/flask/templating.py", line 131, in _render
    rv = template.render(context)
  File "/Users/julianfichtinger/Library/CloudStorage/OneDrive-HTLWien3Rennweg/4. Jahr/1. Semester/ITP/Heatseekers/.venv/lib/python3.13/site-packages/jinja2/environment.py", line 1304, in render
    self.environment.handle_exception()
    ~~~~~~~~~~~~~~~~~~~~~~~~~~~~~~~~~^^
  File "/Users/julianfichtinger/Library/CloudStorage/OneDrive-HTLWien3Rennweg/4. Jahr/1. Semester/ITP/Heatseekers/.venv/lib/python3.13/site-packages/jinja2/environment.py", line 939, in handle_exception
    raise rewrite_traceback_stack(source=source)
  File "<template>", line 20, in top-level template code
  File "/Users/julianfichtinger/Library/CloudStorage/OneDrive-HTLWien3Rennweg/4. Jahr/1. Semester/ITP/Heatseekers/.venv/lib/python3.13/site-packages/flask/app.py", line 1084, in url_for
    return self.handle_url_build_error(error, endpoint, values)
           ~~~~~~~~~~~~~~~~~~~~~~~~~~~^^^^^^^^^^^^^^^^^^^^^^^^^
  File "/Users/julianfichtinger/Library/CloudStorage/OneDrive-HTLWien3Rennweg/4. Jahr/1. Semester/ITP/Heatseekers/.venv/lib/python3.13/site-packages/flask/app.py", line 1073, in url_for
    rv = url_adapter.build(  # type: ignore[union-attr]
        endpoint,
    ...<3 lines>...
        force_external=_external,
    )
  File "/Users/julianfichtinger/Library/CloudStorage/OneDrive-HTLWien3Rennweg/4. Jahr/1. Semester/ITP/Heatseekers/.venv/lib/python3.13/site-packages/werkzeug/routing/map.py", line 924, in build
    raise BuildError(endpoint, values, method, self)
werkzeug.routing.exceptions.BuildError: Could not build url for endpoint 'home'. Did you mean 'view' instead?

During handling of the above exception, another exception occurred:

Traceback (most recent call last):
  File "/Users/julianfichtinger/Library/CloudStorage/OneDrive-HTLWien3Rennweg/4. Jahr/1. Semester/ITP/Heatseekers/.venv/lib/python3.13/site-packages/flask/app.py", line 1473, in wsgi_app
    response = self.full_dispatch_request()
  File "/Users/julianfichtinger/Library/CloudStorage/OneDrive-HTLWien3Rennweg/4. Jahr/1. Semester/ITP/Heatseekers/.venv/lib/python3.13/site-packages/flask/app.py", line 882, in full_dispatch_request
    rv = self.handle_user_exception(e)
  File "/Users/julianfichtinger/Library/CloudStorage/OneDrive-HTLWien3Rennweg/4. Jahr/1. Semester/ITP/Heatseekers/.venv/lib/python3.13/site-packages/flask/app.py", line 772, in handle_user_exception
    return self.ensure_sync(handler)(e)  # type: ignore[no-any-return]
           ~~~~~~~~~~~~~~~~~~~~~~~~~^^^
TypeError: errorhandler() takes 0 positional arguments but 1 was given
2024-11-05 16:15:00,754 - INFO - 127.0.0.1 - - [05/Nov/2024 16:15:00] "[35m[1mGET /error HTTP/1.1[0m" 500 -
2024-11-05 16:15:00,755 - ERROR - Error on request:
Traceback (most recent call last):
  File "/Users/julianfichtinger/Library/CloudStorage/OneDrive-HTLWien3Rennweg/4. Jahr/1. Semester/ITP/Heatseekers/.venv/lib/python3.13/site-packages/flask/app.py", line 880, in full_dispatch_request
    rv = self.dispatch_request()
  File "/Users/julianfichtinger/Library/CloudStorage/OneDrive-HTLWien3Rennweg/4. Jahr/1. Semester/ITP/Heatseekers/.venv/lib/python3.13/site-packages/flask/app.py", line 865, in dispatch_request
    return self.ensure_sync(self.view_functions[rule.endpoint])(**view_args)  # type: ignore[no-any-return]
           ~~~~~~~~~~~~~~~~~~~~~~~~~~~~~~~~~~~~~~~~~~~~~~~~~~~~^^^^^^^^^^^^^
  File "/Users/julianfichtinger/Library/CloudStorage/OneDrive-HTLWien3Rennweg/4. Jahr/1. Semester/ITP/Heatseekers/server.py", line 55, in error
    return render_template_string(functions.read_file("templates/ErrorPage.html"))
  File "/Users/julianfichtinger/Library/CloudStorage/OneDrive-HTLWien3Rennweg/4. Jahr/1. Semester/ITP/Heatseekers/.venv/lib/python3.13/site-packages/flask/templating.py", line 162, in render_template_string
    return _render(app, template, context)
  File "/Users/julianfichtinger/Library/CloudStorage/OneDrive-HTLWien3Rennweg/4. Jahr/1. Semester/ITP/Heatseekers/.venv/lib/python3.13/site-packages/flask/templating.py", line 131, in _render
    rv = template.render(context)
  File "/Users/julianfichtinger/Library/CloudStorage/OneDrive-HTLWien3Rennweg/4. Jahr/1. Semester/ITP/Heatseekers/.venv/lib/python3.13/site-packages/jinja2/environment.py", line 1304, in render
    self.environment.handle_exception()
    ~~~~~~~~~~~~~~~~~~~~~~~~~~~~~~~~~^^
  File "/Users/julianfichtinger/Library/CloudStorage/OneDrive-HTLWien3Rennweg/4. Jahr/1. Semester/ITP/Heatseekers/.venv/lib/python3.13/site-packages/jinja2/environment.py", line 939, in handle_exception
    raise rewrite_traceback_stack(source=source)
  File "<template>", line 20, in top-level template code
  File "/Users/julianfichtinger/Library/CloudStorage/OneDrive-HTLWien3Rennweg/4. Jahr/1. Semester/ITP/Heatseekers/.venv/lib/python3.13/site-packages/flask/app.py", line 1084, in url_for
    return self.handle_url_build_error(error, endpoint, values)
           ~~~~~~~~~~~~~~~~~~~~~~~~~~~^^^^^^^^^^^^^^^^^^^^^^^^^
  File "/Users/julianfichtinger/Library/CloudStorage/OneDrive-HTLWien3Rennweg/4. Jahr/1. Semester/ITP/Heatseekers/.venv/lib/python3.13/site-packages/flask/app.py", line 1073, in url_for
    rv = url_adapter.build(  # type: ignore[union-attr]
    
  File "/Users/julianfichtinger/Library/CloudStorage/OneDrive-HTLWien3Rennweg/4. Jahr/1. Semester/ITP/Heatseekers/.venv/lib/python3.13/site-packages/werkzeug/routing/map.py", line 924, in build
    raise BuildError(endpoint, values, method, self)
werkzeug.routing.exceptions.BuildError: Could not build url for endpoint 'home'. Did you mean 'view' instead?

During handling of the above exception, another exception occurred:

Traceback (most recent call last):
  File "/Users/julianfichtinger/Library/CloudStorage/OneDrive-HTLWien3Rennweg/4. Jahr/1. Semester/ITP/Heatseekers/.venv/lib/python3.13/site-packages/flask/app.py", line 1473, in wsgi_app
    response = self.full_dispatch_request()
  File "/Users/julianfichtinger/Library/CloudStorage/OneDrive-HTLWien3Rennweg/4. Jahr/1. Semester/ITP/Heatseekers/.venv/lib/python3.13/site-packages/flask/app.py", line 882, in full_dispatch_request
    rv = self.handle_user_exception(e)
  File "/Users/julianfichtinger/Library/CloudStorage/OneDrive-HTLWien3Rennweg/4. Jahr/1. Semester/ITP/Heatseekers/.venv/lib/python3.13/site-packages/flask/app.py", line 772, in handle_user_exception
    return self.ensure_sync(handler)(e)  # type: ignore[no-any-return]
           ~~~~~~~~~~~~~~~~~~~~~~~~~^^^
TypeError: errorhandler() takes 0 positional arguments but 1 was given

During handling of the above exception, another exception occurred:

Traceback (most recent call last):
  File "/Users/julianfichtinger/Library/CloudStorage/OneDrive-HTLWien3Rennweg/4. Jahr/1. Semester/ITP/Heatseekers/.venv/lib/python3.13/site-packages/werkzeug/serving.py", line 370, in run_wsgi
    execute(self.server.app)
    ~~~~~~~^^^^^^^^^^^^^^^^^
  File "/Users/julianfichtinger/Library/CloudStorage/OneDrive-HTLWien3Rennweg/4. Jahr/1. Semester/ITP/Heatseekers/.venv/lib/python3.13/site-packages/werkzeug/serving.py", line 331, in execute
    application_iter = app(environ, start_response)
  File "/Users/julianfichtinger/Library/CloudStorage/OneDrive-HTLWien3Rennweg/4. Jahr/1. Semester/ITP/Heatseekers/.venv/lib/python3.13/site-packages/flask/app.py", line 1498, in __call__
    return self.wsgi_app(environ, start_response)
           ~~~~~~~~~~~~~^^^^^^^^^^^^^^^^^^^^^^^^^
  File "/Users/julianfichtinger/Library/CloudStorage/OneDrive-HTLWien3Rennweg/4. Jahr/1. Semester/ITP/Heatseekers/.venv/lib/python3.13/site-packages/flask/app.py", line 1476, in wsgi_app
    response = self.handle_exception(e)
  File "/Users/julianfichtinger/Library/CloudStorage/OneDrive-HTLWien3Rennweg/4. Jahr/1. Semester/ITP/Heatseekers/.venv/lib/python3.13/site-packages/flask/app.py", line 823, in handle_exception
    server_error = self.ensure_sync(handler)(server_error)
TypeError: errorhandler() takes 0 positional arguments but 1 was given
2024-11-05 16:15:00,889 - INFO - Error page accessed
2024-11-05 16:15:00,890 - ERROR - Exception on /error [GET]
Traceback (most recent call last):
  File "/Users/julianfichtinger/Library/CloudStorage/OneDrive-HTLWien3Rennweg/4. Jahr/1. Semester/ITP/Heatseekers/.venv/lib/python3.13/site-packages/flask/app.py", line 880, in full_dispatch_request
    rv = self.dispatch_request()
  File "/Users/julianfichtinger/Library/CloudStorage/OneDrive-HTLWien3Rennweg/4. Jahr/1. Semester/ITP/Heatseekers/.venv/lib/python3.13/site-packages/flask/app.py", line 865, in dispatch_request
    return self.ensure_sync(self.view_functions[rule.endpoint])(**view_args)  # type: ignore[no-any-return]
           ~~~~~~~~~~~~~~~~~~~~~~~~~~~~~~~~~~~~~~~~~~~~~~~~~~~~^^^^^^^^^^^^^
  File "/Users/julianfichtinger/Library/CloudStorage/OneDrive-HTLWien3Rennweg/4. Jahr/1. Semester/ITP/Heatseekers/server.py", line 55, in error
    return render_template_string(functions.read_file("templates/ErrorPage.html"))
  File "/Users/julianfichtinger/Library/CloudStorage/OneDrive-HTLWien3Rennweg/4. Jahr/1. Semester/ITP/Heatseekers/.venv/lib/python3.13/site-packages/flask/templating.py", line 162, in render_template_string
    return _render(app, template, context)
  File "/Users/julianfichtinger/Library/CloudStorage/OneDrive-HTLWien3Rennweg/4. Jahr/1. Semester/ITP/Heatseekers/.venv/lib/python3.13/site-packages/flask/templating.py", line 131, in _render
    rv = template.render(context)
  File "/Users/julianfichtinger/Library/CloudStorage/OneDrive-HTLWien3Rennweg/4. Jahr/1. Semester/ITP/Heatseekers/.venv/lib/python3.13/site-packages/jinja2/environment.py", line 1304, in render
    self.environment.handle_exception()
    ~~~~~~~~~~~~~~~~~~~~~~~~~~~~~~~~~^^
  File "/Users/julianfichtinger/Library/CloudStorage/OneDrive-HTLWien3Rennweg/4. Jahr/1. Semester/ITP/Heatseekers/.venv/lib/python3.13/site-packages/jinja2/environment.py", line 939, in handle_exception
    raise rewrite_traceback_stack(source=source)
  File "<template>", line 20, in top-level template code
  File "/Users/julianfichtinger/Library/CloudStorage/OneDrive-HTLWien3Rennweg/4. Jahr/1. Semester/ITP/Heatseekers/.venv/lib/python3.13/site-packages/flask/app.py", line 1084, in url_for
    return self.handle_url_build_error(error, endpoint, values)
           ~~~~~~~~~~~~~~~~~~~~~~~~~~~^^^^^^^^^^^^^^^^^^^^^^^^^
  File "/Users/julianfichtinger/Library/CloudStorage/OneDrive-HTLWien3Rennweg/4. Jahr/1. Semester/ITP/Heatseekers/.venv/lib/python3.13/site-packages/flask/app.py", line 1073, in url_for
    rv = url_adapter.build(  # type: ignore[union-attr]
        endpoint,
    ...<3 lines>...
        force_external=_external,
    )
  File "/Users/julianfichtinger/Library/CloudStorage/OneDrive-HTLWien3Rennweg/4. Jahr/1. Semester/ITP/Heatseekers/.venv/lib/python3.13/site-packages/werkzeug/routing/map.py", line 924, in build
    raise BuildError(endpoint, values, method, self)
werkzeug.routing.exceptions.BuildError: Could not build url for endpoint 'home'. Did you mean 'view' instead?

During handling of the above exception, another exception occurred:

Traceback (most recent call last):
  File "/Users/julianfichtinger/Library/CloudStorage/OneDrive-HTLWien3Rennweg/4. Jahr/1. Semester/ITP/Heatseekers/.venv/lib/python3.13/site-packages/flask/app.py", line 1473, in wsgi_app
    response = self.full_dispatch_request()
  File "/Users/julianfichtinger/Library/CloudStorage/OneDrive-HTLWien3Rennweg/4. Jahr/1. Semester/ITP/Heatseekers/.venv/lib/python3.13/site-packages/flask/app.py", line 882, in full_dispatch_request
    rv = self.handle_user_exception(e)
  File "/Users/julianfichtinger/Library/CloudStorage/OneDrive-HTLWien3Rennweg/4. Jahr/1. Semester/ITP/Heatseekers/.venv/lib/python3.13/site-packages/flask/app.py", line 772, in handle_user_exception
    return self.ensure_sync(handler)(e)  # type: ignore[no-any-return]
           ~~~~~~~~~~~~~~~~~~~~~~~~~^^^
TypeError: errorhandler() takes 0 positional arguments but 1 was given
2024-11-05 16:15:00,894 - INFO - 127.0.0.1 - - [05/Nov/2024 16:15:00] "[35m[1mGET /error HTTP/1.1[0m" 500 -
2024-11-05 16:15:00,895 - ERROR - Error on request:
Traceback (most recent call last):
  File "/Users/julianfichtinger/Library/CloudStorage/OneDrive-HTLWien3Rennweg/4. Jahr/1. Semester/ITP/Heatseekers/.venv/lib/python3.13/site-packages/flask/app.py", line 880, in full_dispatch_request
    rv = self.dispatch_request()
  File "/Users/julianfichtinger/Library/CloudStorage/OneDrive-HTLWien3Rennweg/4. Jahr/1. Semester/ITP/Heatseekers/.venv/lib/python3.13/site-packages/flask/app.py", line 865, in dispatch_request
    return self.ensure_sync(self.view_functions[rule.endpoint])(**view_args)  # type: ignore[no-any-return]
           ~~~~~~~~~~~~~~~~~~~~~~~~~~~~~~~~~~~~~~~~~~~~~~~~~~~~^^^^^^^^^^^^^
  File "/Users/julianfichtinger/Library/CloudStorage/OneDrive-HTLWien3Rennweg/4. Jahr/1. Semester/ITP/Heatseekers/server.py", line 55, in error
    return render_template_string(functions.read_file("templates/ErrorPage.html"))
  File "/Users/julianfichtinger/Library/CloudStorage/OneDrive-HTLWien3Rennweg/4. Jahr/1. Semester/ITP/Heatseekers/.venv/lib/python3.13/site-packages/flask/templating.py", line 162, in render_template_string
    return _render(app, template, context)
  File "/Users/julianfichtinger/Library/CloudStorage/OneDrive-HTLWien3Rennweg/4. Jahr/1. Semester/ITP/Heatseekers/.venv/lib/python3.13/site-packages/flask/templating.py", line 131, in _render
    rv = template.render(context)
  File "/Users/julianfichtinger/Library/CloudStorage/OneDrive-HTLWien3Rennweg/4. Jahr/1. Semester/ITP/Heatseekers/.venv/lib/python3.13/site-packages/jinja2/environment.py", line 1304, in render
    self.environment.handle_exception()
    ~~~~~~~~~~~~~~~~~~~~~~~~~~~~~~~~~^^
  File "/Users/julianfichtinger/Library/CloudStorage/OneDrive-HTLWien3Rennweg/4. Jahr/1. Semester/ITP/Heatseekers/.venv/lib/python3.13/site-packages/jinja2/environment.py", line 939, in handle_exception
    raise rewrite_traceback_stack(source=source)
  File "<template>", line 20, in top-level template code
  File "/Users/julianfichtinger/Library/CloudStorage/OneDrive-HTLWien3Rennweg/4. Jahr/1. Semester/ITP/Heatseekers/.venv/lib/python3.13/site-packages/flask/app.py", line 1084, in url_for
    return self.handle_url_build_error(error, endpoint, values)
           ~~~~~~~~~~~~~~~~~~~~~~~~~~~^^^^^^^^^^^^^^^^^^^^^^^^^
  File "/Users/julianfichtinger/Library/CloudStorage/OneDrive-HTLWien3Rennweg/4. Jahr/1. Semester/ITP/Heatseekers/.venv/lib/python3.13/site-packages/flask/app.py", line 1073, in url_for
    rv = url_adapter.build(  # type: ignore[union-attr]
    
  File "/Users/julianfichtinger/Library/CloudStorage/OneDrive-HTLWien3Rennweg/4. Jahr/1. Semester/ITP/Heatseekers/.venv/lib/python3.13/site-packages/werkzeug/routing/map.py", line 924, in build
    raise BuildError(endpoint, values, method, self)
werkzeug.routing.exceptions.BuildError: Could not build url for endpoint 'home'. Did you mean 'view' instead?

During handling of the above exception, another exception occurred:

Traceback (most recent call last):
  File "/Users/julianfichtinger/Library/CloudStorage/OneDrive-HTLWien3Rennweg/4. Jahr/1. Semester/ITP/Heatseekers/.venv/lib/python3.13/site-packages/flask/app.py", line 1473, in wsgi_app
    response = self.full_dispatch_request()
  File "/Users/julianfichtinger/Library/CloudStorage/OneDrive-HTLWien3Rennweg/4. Jahr/1. Semester/ITP/Heatseekers/.venv/lib/python3.13/site-packages/flask/app.py", line 882, in full_dispatch_request
    rv = self.handle_user_exception(e)
  File "/Users/julianfichtinger/Library/CloudStorage/OneDrive-HTLWien3Rennweg/4. Jahr/1. Semester/ITP/Heatseekers/.venv/lib/python3.13/site-packages/flask/app.py", line 772, in handle_user_exception
    return self.ensure_sync(handler)(e)  # type: ignore[no-any-return]
           ~~~~~~~~~~~~~~~~~~~~~~~~~^^^
TypeError: errorhandler() takes 0 positional arguments but 1 was given

During handling of the above exception, another exception occurred:

Traceback (most recent call last):
  File "/Users/julianfichtinger/Library/CloudStorage/OneDrive-HTLWien3Rennweg/4. Jahr/1. Semester/ITP/Heatseekers/.venv/lib/python3.13/site-packages/werkzeug/serving.py", line 370, in run_wsgi
    execute(self.server.app)
    ~~~~~~~^^^^^^^^^^^^^^^^^
  File "/Users/julianfichtinger/Library/CloudStorage/OneDrive-HTLWien3Rennweg/4. Jahr/1. Semester/ITP/Heatseekers/.venv/lib/python3.13/site-packages/werkzeug/serving.py", line 331, in execute
    application_iter = app(environ, start_response)
  File "/Users/julianfichtinger/Library/CloudStorage/OneDrive-HTLWien3Rennweg/4. Jahr/1. Semester/ITP/Heatseekers/.venv/lib/python3.13/site-packages/flask/app.py", line 1498, in __call__
    return self.wsgi_app(environ, start_response)
           ~~~~~~~~~~~~~^^^^^^^^^^^^^^^^^^^^^^^^^
  File "/Users/julianfichtinger/Library/CloudStorage/OneDrive-HTLWien3Rennweg/4. Jahr/1. Semester/ITP/Heatseekers/.venv/lib/python3.13/site-packages/flask/app.py", line 1476, in wsgi_app
    response = self.handle_exception(e)
  File "/Users/julianfichtinger/Library/CloudStorage/OneDrive-HTLWien3Rennweg/4. Jahr/1. Semester/ITP/Heatseekers/.venv/lib/python3.13/site-packages/flask/app.py", line 823, in handle_exception
    server_error = self.ensure_sync(handler)(server_error)
TypeError: errorhandler() takes 0 positional arguments but 1 was given
