2024-11-05 16:18:19,903 - INFO - Server started, log file: ./logs/2024-11-05_16-18-19.log
2024-11-05 16:18:19,921 - INFO - [31m[1mWARNING: This is a development server. Do not use it in a production deployment. Use a production WSGI server instead.[0m
 * Running on all addresses (0.0.0.0)
 * Running on http://127.0.0.1:8000
 * Running on http://10.21.16.131:8000
2024-11-05 16:18:19,921 - INFO - [33mPress CTRL+C to quit[0m
2024-11-05 16:18:21,408 - INFO - Login page accessed
2024-11-05 16:18:21,410 - INFO - 10.21.16.131 - - [05/Nov/2024 16:18:21] "GET / HTTP/1.1" 200 -
2024-11-05 16:18:21,413 - INFO - 10.21.16.131 - - [05/Nov/2024 16:18:21] "[36mGET /static/LoginPage.css HTTP/1.1[0m" 304 -
2024-11-05 16:18:21,421 - INFO - 10.21.16.131 - - [05/Nov/2024 16:18:21] "[36mGET /static/LoginPage.css HTTP/1.1[0m" 304 -
2024-11-05 16:18:24,199 - INFO - Login page accessed
2024-11-05 16:18:24,205 - INFO - 10.21.16.131 - - [05/Nov/2024 16:18:24] "GET / HTTP/1.1" 200 -
2024-11-05 16:18:24,207 - INFO - 10.21.16.131 - - [05/Nov/2024 16:18:24] "[36mGET /static/LoginPage.css HTTP/1.1[0m" 304 -
2024-11-05 16:18:24,218 - INFO - 10.21.16.131 - - [05/Nov/2024 16:18:24] "[36mGET /static/LoginPage.css HTTP/1.1[0m" 304 -
2024-11-05 16:18:25,203 - ERROR - Exception on /view [GET]
Traceback (most recent call last):
  File "/Users/julianfichtinger/Library/CloudStorage/OneDrive-HTLWien3Rennweg/4. Jahr/1. Semester/ITP/Heatseekers/.venv/lib/python3.13/site-packages/flask/app.py", line 880, in full_dispatch_request
    rv = self.dispatch_request()
  File "/Users/julianfichtinger/Library/CloudStorage/OneDrive-HTLWien3Rennweg/4. Jahr/1. Semester/ITP/Heatseekers/.venv/lib/python3.13/site-packages/flask/app.py", line 854, in dispatch_request
    self.raise_routing_exception(req)
    ~~~~~~~~~~~~~~~~~~~~~~~~~~~~^^^^^
  File "/Users/julianfichtinger/Library/CloudStorage/OneDrive-HTLWien3Rennweg/4. Jahr/1. Semester/ITP/Heatseekers/.venv/lib/python3.13/site-packages/flask/app.py", line 463, in raise_routing_exception
    raise request.routing_exception  # type: ignore[misc]
    ^^^^^^^^^^^^^^^^^^^^^^^^^^^^^^^
  File "/Users/julianfichtinger/Library/CloudStorage/OneDrive-HTLWien3Rennweg/4. Jahr/1. Semester/ITP/Heatseekers/.venv/lib/python3.13/site-packages/flask/ctx.py", line 362, in match_request
    result = self.url_adapter.match(return_rule=True)  # type: ignore
  File "/Users/julianfichtinger/Library/CloudStorage/OneDrive-HTLWien3Rennweg/4. Jahr/1. Semester/ITP/Heatseekers/.venv/lib/python3.13/site-packages/werkzeug/routing/map.py", line 624, in match
    raise MethodNotAllowed(valid_methods=list(e.have_match_for)) from None
werkzeug.exceptions.MethodNotAllowed: 405 Method Not Allowed: The method is not allowed for the requested URL.

During handling of the above exception, another exception occurred:

Traceback (most recent call last):
  File "/Users/julianfichtinger/Library/CloudStorage/OneDrive-HTLWien3Rennweg/4. Jahr/1. Semester/ITP/Heatseekers/.venv/lib/python3.13/site-packages/flask/app.py", line 1473, in wsgi_app
    response = self.full_dispatch_request()
  File "/Users/julianfichtinger/Library/CloudStorage/OneDrive-HTLWien3Rennweg/4. Jahr/1. Semester/ITP/Heatseekers/.venv/lib/python3.13/site-packages/flask/app.py", line 882, in full_dispatch_request
    rv = self.handle_user_exception(e)
  File "/Users/julianfichtinger/Library/CloudStorage/OneDrive-HTLWien3Rennweg/4. Jahr/1. Semester/ITP/Heatseekers/.venv/lib/python3.13/site-packages/flask/app.py", line 765, in handle_user_exception
    return self.handle_http_exception(e)
           ~~~~~~~~~~~~~~~~~~~~~~~~~~^^^
  File "/Users/julianfichtinger/Library/CloudStorage/OneDrive-HTLWien3Rennweg/4. Jahr/1. Semester/ITP/Heatseekers/.venv/lib/python3.13/site-packages/flask/app.py", line 740, in handle_http_exception
    return self.ensure_sync(handler)(e)  # type: ignore[no-any-return]
           ~~~~~~~~~~~~~~~~~~~~~~~~~^^^
TypeError: errorhandler() takes 0 positional arguments but 1 was given
2024-11-05 16:18:25,210 - INFO - 10.21.16.131 - - [05/Nov/2024 16:18:25] "[35m[1mGET /view HTTP/1.1[0m" 500 -
2024-11-05 16:18:25,232 - ERROR - Error on request:
Traceback (most recent call last):
  File "/Users/julianfichtinger/Library/CloudStorage/OneDrive-HTLWien3Rennweg/4. Jahr/1. Semester/ITP/Heatseekers/.venv/lib/python3.13/site-packages/flask/app.py", line 880, in full_dispatch_request
    rv = self.dispatch_request()
  File "/Users/julianfichtinger/Library/CloudStorage/OneDrive-HTLWien3Rennweg/4. Jahr/1. Semester/ITP/Heatseekers/.venv/lib/python3.13/site-packages/flask/app.py", line 854, in dispatch_request
    self.raise_routing_exception(req)
    ~~~~~~~~~~~~~~~~~~~~~~~~~~~~^^^^^
  File "/Users/julianfichtinger/Library/CloudStorage/OneDrive-HTLWien3Rennweg/4. Jahr/1. Semester/ITP/Heatseekers/.venv/lib/python3.13/site-packages/flask/app.py", line 463, in raise_routing_exception
    raise request.routing_exception  # type: ignore[misc]
    ^^^^^^^^^^^^^^^^^^^^^^^^^^^^^^^
  File "/Users/julianfichtinger/Library/CloudStorage/OneDrive-HTLWien3Rennweg/4. Jahr/1. Semester/ITP/Heatseekers/.venv/lib/python3.13/site-packages/flask/ctx.py", line 362, in match_request
    result = self.url_adapter.match(return_rule=True)  # type: ignore
  File "/Users/julianfichtinger/Library/CloudStorage/OneDrive-HTLWien3Rennweg/4. Jahr/1. Semester/ITP/Heatseekers/.venv/lib/python3.13/site-packages/werkzeug/routing/map.py", line 624, in match
    raise MethodNotAllowed(valid_methods=list(e.have_match_for)) from None
werkzeug.exceptions.MethodNotAllowed: 405 Method Not Allowed: The method is not allowed for the requested URL.

During handling of the above exception, another exception occurred:

Traceback (most recent call last):
  File "/Users/julianfichtinger/Library/CloudStorage/OneDrive-HTLWien3Rennweg/4. Jahr/1. Semester/ITP/Heatseekers/.venv/lib/python3.13/site-packages/flask/app.py", line 1473, in wsgi_app
    response = self.full_dispatch_request()
  File "/Users/julianfichtinger/Library/CloudStorage/OneDrive-HTLWien3Rennweg/4. Jahr/1. Semester/ITP/Heatseekers/.venv/lib/python3.13/site-packages/flask/app.py", line 882, in full_dispatch_request
    rv = self.handle_user_exception(e)
  File "/Users/julianfichtinger/Library/CloudStorage/OneDrive-HTLWien3Rennweg/4. Jahr/1. Semester/ITP/Heatseekers/.venv/lib/python3.13/site-packages/flask/app.py", line 765, in handle_user_exception
    return self.handle_http_exception(e)
           ~~~~~~~~~~~~~~~~~~~~~~~~~~^^^
  File "/Users/julianfichtinger/Library/CloudStorage/OneDrive-HTLWien3Rennweg/4. Jahr/1. Semester/ITP/Heatseekers/.venv/lib/python3.13/site-packages/flask/app.py", line 740, in handle_http_exception
    return self.ensure_sync(handler)(e)  # type: ignore[no-any-return]
           ~~~~~~~~~~~~~~~~~~~~~~~~~^^^
TypeError: errorhandler() takes 0 positional arguments but 1 was given

During handling of the above exception, another exception occurred:

Traceback (most recent call last):
  File "/Users/julianfichtinger/Library/CloudStorage/OneDrive-HTLWien3Rennweg/4. Jahr/1. Semester/ITP/Heatseekers/.venv/lib/python3.13/site-packages/werkzeug/serving.py", line 370, in run_wsgi
    execute(self.server.app)
    ~~~~~~~^^^^^^^^^^^^^^^^^
  File "/Users/julianfichtinger/Library/CloudStorage/OneDrive-HTLWien3Rennweg/4. Jahr/1. Semester/ITP/Heatseekers/.venv/lib/python3.13/site-packages/werkzeug/serving.py", line 331, in execute
    application_iter = app(environ, start_response)
  File "/Users/julianfichtinger/Library/CloudStorage/OneDrive-HTLWien3Rennweg/4. Jahr/1. Semester/ITP/Heatseekers/.venv/lib/python3.13/site-packages/flask/app.py", line 1498, in __call__
    return self.wsgi_app(environ, start_response)
           ~~~~~~~~~~~~~^^^^^^^^^^^^^^^^^^^^^^^^^
  File "/Users/julianfichtinger/Library/CloudStorage/OneDrive-HTLWien3Rennweg/4. Jahr/1. Semester/ITP/Heatseekers/.venv/lib/python3.13/site-packages/flask/app.py", line 1476, in wsgi_app
    response = self.handle_exception(e)
  File "/Users/julianfichtinger/Library/CloudStorage/OneDrive-HTLWien3Rennweg/4. Jahr/1. Semester/ITP/Heatseekers/.venv/lib/python3.13/site-packages/flask/app.py", line 823, in handle_exception
    server_error = self.ensure_sync(handler)(server_error)
TypeError: errorhandler() takes 0 positional arguments but 1 was given
