2024-11-05 16:12:26,040 - INFO - Server started, log file: ./logs/2024-11-05_16-12-26.log
2024-11-05 16:12:26,060 - INFO - [31m[1mWARNING: This is a development server. Do not use it in a production deployment. Use a production WSGI server instead.[0m
 * Running on all addresses (0.0.0.0)
 * Running on http://127.0.0.1:8000
 * Running on http://10.21.16.131:8000
2024-11-05 16:12:26,060 - INFO - [33mPress CTRL+C to quit[0m
2024-11-05 16:12:29,346 - INFO - Login page accessed
2024-11-05 16:12:29,349 - INFO - 10.21.16.131 - - [05/Nov/2024 16:12:29] "GET / HTTP/1.1" 200 -
2024-11-05 16:12:29,356 - INFO - 10.21.16.131 - - [05/Nov/2024 16:12:29] "[36mGET /static/LoginPage.css HTTP/1.1[0m" 304 -
2024-11-05 16:12:31,491 - INFO - Error page accessed
2024-11-05 16:12:31,498 - ERROR - Exception on /error [GET]
Traceback (most recent call last):
  File "/Users/julianfichtinger/Library/CloudStorage/OneDrive-HTLWien3Rennweg/4. Jahr/1. Semester/ITP/Heatseekers/.venv/lib/python3.13/site-packages/flask/app.py", line 880, in full_dispatch_request
    rv = self.dispatch_request()
  File "/Users/julianfichtinger/Library/CloudStorage/OneDrive-HTLWien3Rennweg/4. Jahr/1. Semester/ITP/Heatseekers/.venv/lib/python3.13/site-packages/flask/app.py", line 865, in dispatch_request
    return self.ensure_sync(self.view_functions[rule.endpoint])(**view_args)  # type: ignore[no-any-return]
           ~~~~~~~~~~~~~~~~~~~~~~~~~~~~~~~~~~~~~~~~~~~~~~~~~~~~^^^^^^^^^^^^^
  File "/Users/julianfichtinger/Library/CloudStorage/OneDrive-HTLWien3Rennweg/4. Jahr/1. Semester/ITP/Heatseekers/server.py", line 55, in error
    return render_template_string(functions.read_file("templates/ErrorPage.html"))
  File "/Users/julianfichtinger/Library/CloudStorage/OneDrive-HTLWien3Rennweg/4. Jahr/1. Semester/ITP/Heatseekers/.venv/lib/python3.13/site-packages/flask/templating.py", line 162, in render_template_string
    return _render(app, template, context)
  File "/Users/julianfichtinger/Library/CloudStorage/OneDrive-HTLWien3Rennweg/4. Jahr/1. Semester/ITP/Heatseekers/.venv/lib/python3.13/site-packages/flask/templating.py", line 131, in _render
    rv = template.render(context)
  File "/Users/julianfichtinger/Library/CloudStorage/OneDrive-HTLWien3Rennweg/4. Jahr/1. Semester/ITP/Heatseekers/.venv/lib/python3.13/site-packages/jinja2/environment.py", line 1304, in render
    self.environment.handle_exception()
    ~~~~~~~~~~~~~~~~~~~~~~~~~~~~~~~~~^^
  File "/Users/julianfichtinger/Library/CloudStorage/OneDrive-HTLWien3Rennweg/4. Jahr/1. Semester/ITP/Heatseekers/.venv/lib/python3.13/site-packages/jinja2/environment.py", line 939, in handle_exception
    raise rewrite_traceback_stack(source=source)
  File "<template>", line 20, in top-level template code
  File "/Users/julianfichtinger/Library/CloudStorage/OneDrive-HTLWien3Rennweg/4. Jahr/1. Semester/ITP/Heatseekers/.venv/lib/python3.13/site-packages/flask/app.py", line 1084, in url_for
    return self.handle_url_build_error(error, endpoint, values)
           ~~~~~~~~~~~~~~~~~~~~~~~~~~~^^^^^^^^^^^^^^^^^^^^^^^^^
  File "/Users/julianfichtinger/Library/CloudStorage/OneDrive-HTLWien3Rennweg/4. Jahr/1. Semester/ITP/Heatseekers/.venv/lib/python3.13/site-packages/flask/app.py", line 1073, in url_for
    rv = url_adapter.build(  # type: ignore[union-attr]
        endpoint,
    ...<3 lines>...
        force_external=_external,
    )
  File "/Users/julianfichtinger/Library/CloudStorage/OneDrive-HTLWien3Rennweg/4. Jahr/1. Semester/ITP/Heatseekers/.venv/lib/python3.13/site-packages/werkzeug/routing/map.py", line 924, in build
    raise BuildError(endpoint, values, method, self)
werkzeug.routing.exceptions.BuildError: Could not build url for endpoint 'home'. Did you mean 'view' instead?

During handling of the above exception, another exception occurred:

Traceback (most recent call last):
  File "/Users/julianfichtinger/Library/CloudStorage/OneDrive-HTLWien3Rennweg/4. Jahr/1. Semester/ITP/Heatseekers/.venv/lib/python3.13/site-packages/flask/app.py", line 1473, in wsgi_app
    response = self.full_dispatch_request()
  File "/Users/julianfichtinger/Library/CloudStorage/OneDrive-HTLWien3Rennweg/4. Jahr/1. Semester/ITP/Heatseekers/.venv/lib/python3.13/site-packages/flask/app.py", line 882, in full_dispatch_request
    rv = self.handle_user_exception(e)
  File "/Users/julianfichtinger/Library/CloudStorage/OneDrive-HTLWien3Rennweg/4. Jahr/1. Semester/ITP/Heatseekers/.venv/lib/python3.13/site-packages/flask/app.py", line 772, in handle_user_exception
    return self.ensure_sync(handler)(e)  # type: ignore[no-any-return]
           ~~~~~~~~~~~~~~~~~~~~~~~~~^^^
TypeError: errorhandler() takes 0 positional arguments but 1 was given
2024-11-05 16:12:31,505 - INFO - 10.21.16.131 - - [05/Nov/2024 16:12:31] "[35m[1mGET /error HTTP/1.1[0m" 500 -
2024-11-05 16:12:31,526 - ERROR - Error on request:
Traceback (most recent call last):
  File "/Users/julianfichtinger/Library/CloudStorage/OneDrive-HTLWien3Rennweg/4. Jahr/1. Semester/ITP/Heatseekers/.venv/lib/python3.13/site-packages/flask/app.py", line 880, in full_dispatch_request
    rv = self.dispatch_request()
  File "/Users/julianfichtinger/Library/CloudStorage/OneDrive-HTLWien3Rennweg/4. Jahr/1. Semester/ITP/Heatseekers/.venv/lib/python3.13/site-packages/flask/app.py", line 865, in dispatch_request
    return self.ensure_sync(self.view_functions[rule.endpoint])(**view_args)  # type: ignore[no-any-return]
           ~~~~~~~~~~~~~~~~~~~~~~~~~~~~~~~~~~~~~~~~~~~~~~~~~~~~^^^^^^^^^^^^^
  File "/Users/julianfichtinger/Library/CloudStorage/OneDrive-HTLWien3Rennweg/4. Jahr/1. Semester/ITP/Heatseekers/server.py", line 55, in error
    return render_template_string(functions.read_file("templates/ErrorPage.html"))
  File "/Users/julianfichtinger/Library/CloudStorage/OneDrive-HTLWien3Rennweg/4. Jahr/1. Semester/ITP/Heatseekers/.venv/lib/python3.13/site-packages/flask/templating.py", line 162, in render_template_string
    return _render(app, template, context)
  File "/Users/julianfichtinger/Library/CloudStorage/OneDrive-HTLWien3Rennweg/4. Jahr/1. Semester/ITP/Heatseekers/.venv/lib/python3.13/site-packages/flask/templating.py", line 131, in _render
    rv = template.render(context)
  File "/Users/julianfichtinger/Library/CloudStorage/OneDrive-HTLWien3Rennweg/4. Jahr/1. Semester/ITP/Heatseekers/.venv/lib/python3.13/site-packages/jinja2/environment.py", line 1304, in render
    self.environment.handle_exception()
    ~~~~~~~~~~~~~~~~~~~~~~~~~~~~~~~~~^^
  File "/Users/julianfichtinger/Library/CloudStorage/OneDrive-HTLWien3Rennweg/4. Jahr/1. Semester/ITP/Heatseekers/.venv/lib/python3.13/site-packages/jinja2/environment.py", line 939, in handle_exception
    raise rewrite_traceback_stack(source=source)
  File "<template>", line 20, in top-level template code
  File "/Users/julianfichtinger/Library/CloudStorage/OneDrive-HTLWien3Rennweg/4. Jahr/1. Semester/ITP/Heatseekers/.venv/lib/python3.13/site-packages/flask/app.py", line 1084, in url_for
    return self.handle_url_build_error(error, endpoint, values)
           ~~~~~~~~~~~~~~~~~~~~~~~~~~~^^^^^^^^^^^^^^^^^^^^^^^^^
  File "/Users/julianfichtinger/Library/CloudStorage/OneDrive-HTLWien3Rennweg/4. Jahr/1. Semester/ITP/Heatseekers/.venv/lib/python3.13/site-packages/flask/app.py", line 1073, in url_for
    rv = url_adapter.build(  # type: ignore[union-attr]
    
  File "/Users/julianfichtinger/Library/CloudStorage/OneDrive-HTLWien3Rennweg/4. Jahr/1. Semester/ITP/Heatseekers/.venv/lib/python3.13/site-packages/werkzeug/routing/map.py", line 924, in build
    raise BuildError(endpoint, values, method, self)
werkzeug.routing.exceptions.BuildError: Could not build url for endpoint 'home'. Did you mean 'view' instead?

During handling of the above exception, another exception occurred:

Traceback (most recent call last):
  File "/Users/julianfichtinger/Library/CloudStorage/OneDrive-HTLWien3Rennweg/4. Jahr/1. Semester/ITP/Heatseekers/.venv/lib/python3.13/site-packages/flask/app.py", line 1473, in wsgi_app
    response = self.full_dispatch_request()
  File "/Users/julianfichtinger/Library/CloudStorage/OneDrive-HTLWien3Rennweg/4. Jahr/1. Semester/ITP/Heatseekers/.venv/lib/python3.13/site-packages/flask/app.py", line 882, in full_dispatch_request
    rv = self.handle_user_exception(e)
  File "/Users/julianfichtinger/Library/CloudStorage/OneDrive-HTLWien3Rennweg/4. Jahr/1. Semester/ITP/Heatseekers/.venv/lib/python3.13/site-packages/flask/app.py", line 772, in handle_user_exception
    return self.ensure_sync(handler)(e)  # type: ignore[no-any-return]
           ~~~~~~~~~~~~~~~~~~~~~~~~~^^^
TypeError: errorhandler() takes 0 positional arguments but 1 was given

During handling of the above exception, another exception occurred:

Traceback (most recent call last):
  File "/Users/julianfichtinger/Library/CloudStorage/OneDrive-HTLWien3Rennweg/4. Jahr/1. Semester/ITP/Heatseekers/.venv/lib/python3.13/site-packages/werkzeug/serving.py", line 370, in run_wsgi
    execute(self.server.app)
    ~~~~~~~^^^^^^^^^^^^^^^^^
  File "/Users/julianfichtinger/Library/CloudStorage/OneDrive-HTLWien3Rennweg/4. Jahr/1. Semester/ITP/Heatseekers/.venv/lib/python3.13/site-packages/werkzeug/serving.py", line 331, in execute
    application_iter = app(environ, start_response)
  File "/Users/julianfichtinger/Library/CloudStorage/OneDrive-HTLWien3Rennweg/4. Jahr/1. Semester/ITP/Heatseekers/.venv/lib/python3.13/site-packages/flask/app.py", line 1498, in __call__
    return self.wsgi_app(environ, start_response)
           ~~~~~~~~~~~~~^^^^^^^^^^^^^^^^^^^^^^^^^
  File "/Users/julianfichtinger/Library/CloudStorage/OneDrive-HTLWien3Rennweg/4. Jahr/1. Semester/ITP/Heatseekers/.venv/lib/python3.13/site-packages/flask/app.py", line 1476, in wsgi_app
    response = self.handle_exception(e)
  File "/Users/julianfichtinger/Library/CloudStorage/OneDrive-HTLWien3Rennweg/4. Jahr/1. Semester/ITP/Heatseekers/.venv/lib/python3.13/site-packages/flask/app.py", line 823, in handle_exception
    server_error = self.ensure_sync(handler)(server_error)
TypeError: errorhandler() takes 0 positional arguments but 1 was given
2024-11-05 16:12:31,544 - ERROR - Exception on /favicon.ico [GET]
Traceback (most recent call last):
  File "/Users/julianfichtinger/Library/CloudStorage/OneDrive-HTLWien3Rennweg/4. Jahr/1. Semester/ITP/Heatseekers/.venv/lib/python3.13/site-packages/flask/app.py", line 880, in full_dispatch_request
    rv = self.dispatch_request()
  File "/Users/julianfichtinger/Library/CloudStorage/OneDrive-HTLWien3Rennweg/4. Jahr/1. Semester/ITP/Heatseekers/.venv/lib/python3.13/site-packages/flask/app.py", line 854, in dispatch_request
    self.raise_routing_exception(req)
    ~~~~~~~~~~~~~~~~~~~~~~~~~~~~^^^^^
  File "/Users/julianfichtinger/Library/CloudStorage/OneDrive-HTLWien3Rennweg/4. Jahr/1. Semester/ITP/Heatseekers/.venv/lib/python3.13/site-packages/flask/app.py", line 463, in raise_routing_exception
    raise request.routing_exception  # type: ignore[misc]
    ^^^^^^^^^^^^^^^^^^^^^^^^^^^^^^^
  File "/Users/julianfichtinger/Library/CloudStorage/OneDrive-HTLWien3Rennweg/4. Jahr/1. Semester/ITP/Heatseekers/.venv/lib/python3.13/site-packages/flask/ctx.py", line 362, in match_request
    result = self.url_adapter.match(return_rule=True)  # type: ignore
  File "/Users/julianfichtinger/Library/CloudStorage/OneDrive-HTLWien3Rennweg/4. Jahr/1. Semester/ITP/Heatseekers/.venv/lib/python3.13/site-packages/werkzeug/routing/map.py", line 629, in match
    raise NotFound() from None
werkzeug.exceptions.NotFound: 404 Not Found: The requested URL was not found on the server. If you entered the URL manually please check your spelling and try again.

During handling of the above exception, another exception occurred:

Traceback (most recent call last):
  File "/Users/julianfichtinger/Library/CloudStorage/OneDrive-HTLWien3Rennweg/4. Jahr/1. Semester/ITP/Heatseekers/.venv/lib/python3.13/site-packages/flask/app.py", line 1473, in wsgi_app
    response = self.full_dispatch_request()
  File "/Users/julianfichtinger/Library/CloudStorage/OneDrive-HTLWien3Rennweg/4. Jahr/1. Semester/ITP/Heatseekers/.venv/lib/python3.13/site-packages/flask/app.py", line 882, in full_dispatch_request
    rv = self.handle_user_exception(e)
  File "/Users/julianfichtinger/Library/CloudStorage/OneDrive-HTLWien3Rennweg/4. Jahr/1. Semester/ITP/Heatseekers/.venv/lib/python3.13/site-packages/flask/app.py", line 765, in handle_user_exception
    return self.handle_http_exception(e)
           ~~~~~~~~~~~~~~~~~~~~~~~~~~^^^
  File "/Users/julianfichtinger/Library/CloudStorage/OneDrive-HTLWien3Rennweg/4. Jahr/1. Semester/ITP/Heatseekers/.venv/lib/python3.13/site-packages/flask/app.py", line 740, in handle_http_exception
    return self.ensure_sync(handler)(e)  # type: ignore[no-any-return]
           ~~~~~~~~~~~~~~~~~~~~~~~~~^^^
TypeError: errorhandler() takes 0 positional arguments but 1 was given
2024-11-05 16:12:31,545 - INFO - 10.21.16.131 - - [05/Nov/2024 16:12:31] "[35m[1mGET /favicon.ico HTTP/1.1[0m" 500 -
2024-11-05 16:12:31,547 - ERROR - Error on request:
Traceback (most recent call last):
  File "/Users/julianfichtinger/Library/CloudStorage/OneDrive-HTLWien3Rennweg/4. Jahr/1. Semester/ITP/Heatseekers/.venv/lib/python3.13/site-packages/flask/app.py", line 880, in full_dispatch_request
    rv = self.dispatch_request()
  File "/Users/julianfichtinger/Library/CloudStorage/OneDrive-HTLWien3Rennweg/4. Jahr/1. Semester/ITP/Heatseekers/.venv/lib/python3.13/site-packages/flask/app.py", line 854, in dispatch_request
    self.raise_routing_exception(req)
    ~~~~~~~~~~~~~~~~~~~~~~~~~~~~^^^^^
  File "/Users/julianfichtinger/Library/CloudStorage/OneDrive-HTLWien3Rennweg/4. Jahr/1. Semester/ITP/Heatseekers/.venv/lib/python3.13/site-packages/flask/app.py", line 463, in raise_routing_exception
    raise request.routing_exception  # type: ignore[misc]
    ^^^^^^^^^^^^^^^^^^^^^^^^^^^^^^^
  File "/Users/julianfichtinger/Library/CloudStorage/OneDrive-HTLWien3Rennweg/4. Jahr/1. Semester/ITP/Heatseekers/.venv/lib/python3.13/site-packages/flask/ctx.py", line 362, in match_request
    result = self.url_adapter.match(return_rule=True)  # type: ignore
  File "/Users/julianfichtinger/Library/CloudStorage/OneDrive-HTLWien3Rennweg/4. Jahr/1. Semester/ITP/Heatseekers/.venv/lib/python3.13/site-packages/werkzeug/routing/map.py", line 629, in match
    raise NotFound() from None
werkzeug.exceptions.NotFound: 404 Not Found: The requested URL was not found on the server. If you entered the URL manually please check your spelling and try again.

During handling of the above exception, another exception occurred:

Traceback (most recent call last):
  File "/Users/julianfichtinger/Library/CloudStorage/OneDrive-HTLWien3Rennweg/4. Jahr/1. Semester/ITP/Heatseekers/.venv/lib/python3.13/site-packages/flask/app.py", line 1473, in wsgi_app
    response = self.full_dispatch_request()
  File "/Users/julianfichtinger/Library/CloudStorage/OneDrive-HTLWien3Rennweg/4. Jahr/1. Semester/ITP/Heatseekers/.venv/lib/python3.13/site-packages/flask/app.py", line 882, in full_dispatch_request
    rv = self.handle_user_exception(e)
  File "/Users/julianfichtinger/Library/CloudStorage/OneDrive-HTLWien3Rennweg/4. Jahr/1. Semester/ITP/Heatseekers/.venv/lib/python3.13/site-packages/flask/app.py", line 765, in handle_user_exception
    return self.handle_http_exception(e)
           ~~~~~~~~~~~~~~~~~~~~~~~~~~^^^
  File "/Users/julianfichtinger/Library/CloudStorage/OneDrive-HTLWien3Rennweg/4. Jahr/1. Semester/ITP/Heatseekers/.venv/lib/python3.13/site-packages/flask/app.py", line 740, in handle_http_exception
    return self.ensure_sync(handler)(e)  # type: ignore[no-any-return]
           ~~~~~~~~~~~~~~~~~~~~~~~~~^^^
TypeError: errorhandler() takes 0 positional arguments but 1 was given

During handling of the above exception, another exception occurred:

Traceback (most recent call last):
  File "/Users/julianfichtinger/Library/CloudStorage/OneDrive-HTLWien3Rennweg/4. Jahr/1. Semester/ITP/Heatseekers/.venv/lib/python3.13/site-packages/werkzeug/serving.py", line 370, in run_wsgi
    execute(self.server.app)
    ~~~~~~~^^^^^^^^^^^^^^^^^
  File "/Users/julianfichtinger/Library/CloudStorage/OneDrive-HTLWien3Rennweg/4. Jahr/1. Semester/ITP/Heatseekers/.venv/lib/python3.13/site-packages/werkzeug/serving.py", line 331, in execute
    application_iter = app(environ, start_response)
  File "/Users/julianfichtinger/Library/CloudStorage/OneDrive-HTLWien3Rennweg/4. Jahr/1. Semester/ITP/Heatseekers/.venv/lib/python3.13/site-packages/flask/app.py", line 1498, in __call__
    return self.wsgi_app(environ, start_response)
           ~~~~~~~~~~~~~^^^^^^^^^^^^^^^^^^^^^^^^^
  File "/Users/julianfichtinger/Library/CloudStorage/OneDrive-HTLWien3Rennweg/4. Jahr/1. Semester/ITP/Heatseekers/.venv/lib/python3.13/site-packages/flask/app.py", line 1476, in wsgi_app
    response = self.handle_exception(e)
  File "/Users/julianfichtinger/Library/CloudStorage/OneDrive-HTLWien3Rennweg/4. Jahr/1. Semester/ITP/Heatseekers/.venv/lib/python3.13/site-packages/flask/app.py", line 823, in handle_exception
    server_error = self.ensure_sync(handler)(server_error)
TypeError: errorhandler() takes 0 positional arguments but 1 was given
