2024-11-05 16:33:25,269 - INFO - Server started, log file: ./logs/2024-11-05_16-33-25.log
2024-11-05 16:33:25,274 - INFO - [31m[1mWARNING: This is a development server. Do not use it in a production deployment. Use a production WSGI server instead.[0m
 * Running on all addresses (0.0.0.0)
 * Running on http://127.0.0.1:8000
 * Running on http://10.0.76.44:8000
2024-11-05 16:33:25,274 - INFO - [33mPress CTRL+C to quit[0m
2024-11-05 16:33:29,874 - ERROR - Exception on /view [POST]
Traceback (most recent call last):
  File "/home/weidi/Desktop/4BI/ITP√ú/Heatseekers/PyCharm/.venv/lib/python3.12/site-packages/flask/app.py", line 880, in full_dispatch_request
    rv = self.dispatch_request()
         ^^^^^^^^^^^^^^^^^^^^^^^
  File "/home/weidi/Desktop/4BI/ITP√ú/Heatseekers/PyCharm/.venv/lib/python3.12/site-packages/flask/app.py", line 865, in dispatch_request
    return self.ensure_sync(self.view_functions[rule.endpoint])(**view_args)  # type: ignore[no-any-return]
           ^^^^^^^^^^^^^^^^^^^^^^^^^^^^^^^^^^^^^^^^^^^^^^^^^^^^^^^^^^^^^^^^^
  File "/home/weidi/Desktop/4BI/ITP√ú/Heatseekers/github/server.py", line 39, in view
    print(tmp['isadmin'])
          ~~~^^^^^^^^^^^
KeyError: 'isadmin'

During handling of the above exception, another exception occurred:

Traceback (most recent call last):
  File "/home/weidi/Desktop/4BI/ITP√ú/Heatseekers/PyCharm/.venv/lib/python3.12/site-packages/flask/app.py", line 1473, in wsgi_app
    response = self.full_dispatch_request()
               ^^^^^^^^^^^^^^^^^^^^^^^^^^^^
  File "/home/weidi/Desktop/4BI/ITP√ú/Heatseekers/PyCharm/.venv/lib/python3.12/site-packages/flask/app.py", line 882, in full_dispatch_request
    rv = self.handle_user_exception(e)
         ^^^^^^^^^^^^^^^^^^^^^^^^^^^^^
  File "/home/weidi/Desktop/4BI/ITP√ú/Heatseekers/PyCharm/.venv/lib/python3.12/site-packages/flask/app.py", line 772, in handle_user_exception
    return self.ensure_sync(handler)(e)  # type: ignore[no-any-return]
           ^^^^^^^^^^^^^^^^^^^^^^^^^^^^
TypeError: errorhandler() takes 0 positional arguments but 1 was given
2024-11-05 16:33:29,875 - INFO - 10.0.76.44 - - [05/Nov/2024 16:33:29] "[35m[1mPOST /view HTTP/1.1[0m" 500 -
2024-11-05 16:33:29,889 - ERROR - Error on request:
Traceback (most recent call last):
  File "/home/weidi/Desktop/4BI/ITP√ú/Heatseekers/PyCharm/.venv/lib/python3.12/site-packages/flask/app.py", line 880, in full_dispatch_request
    rv = self.dispatch_request()
         ^^^^^^^^^^^^^^^^^^^^^^^
  File "/home/weidi/Desktop/4BI/ITP√ú/Heatseekers/PyCharm/.venv/lib/python3.12/site-packages/flask/app.py", line 865, in dispatch_request
    return self.ensure_sync(self.view_functions[rule.endpoint])(**view_args)  # type: ignore[no-any-return]
           ^^^^^^^^^^^^^^^^^^^^^^^^^^^^^^^^^^^^^^^^^^^^^^^^^^^^^^^^^^^^^^^^^^^^^^^^^^^^^^^^^^^^^^^^^^^^^^^^
  File "/home/weidi/Desktop/4BI/ITP√ú/Heatseekers/github/server.py", line 39, in view
    print(tmp['isadmin'])
          ^^^^^^^^^^^^^^^
KeyError: 'isadmin'

During handling of the above exception, another exception occurred:

Traceback (most recent call last):
  File "/home/weidi/Desktop/4BI/ITP√ú/Heatseekers/PyCharm/.venv/lib/python3.12/site-packages/flask/app.py", line 1473, in wsgi_app
    response = self.full_dispatch_request()
               ^^^^^^^^^^^^^^^^^^^^^^^^^^^^
  File "/home/weidi/Desktop/4BI/ITP√ú/Heatseekers/PyCharm/.venv/lib/python3.12/site-packages/flask/app.py", line 882, in full_dispatch_request
    rv = self.handle_user_exception(e)
         ^^^^^^^^^^^^^^^^^^^^^^^^^^^^^
  File "/home/weidi/Desktop/4BI/ITP√ú/Heatseekers/PyCharm/.venv/lib/python3.12/site-packages/flask/app.py", line 772, in handle_user_exception
    return self.ensure_sync(handler)(e)  # type: ignore[no-any-return]
           ^^^^^^^^^^^^^^^^^^^^^^^^^^^^^^^^^^^^^^^^^^^^^^^^^^^^^^^^^^^
TypeError: errorhandler() takes 0 positional arguments but 1 was given

During handling of the above exception, another exception occurred:

Traceback (most recent call last):
  File "/home/weidi/Desktop/4BI/ITP√ú/Heatseekers/PyCharm/.venv/lib/python3.12/site-packages/werkzeug/serving.py", line 370, in run_wsgi
    execute(self.server.app)
  File "/home/weidi/Desktop/4BI/ITP√ú/Heatseekers/PyCharm/.venv/lib/python3.12/site-packages/werkzeug/serving.py", line 331, in execute
    application_iter = app(environ, start_response)
                       ^^^^^^^^^^^^^^^^^^^^^^^^^^^^
  File "/home/weidi/Desktop/4BI/ITP√ú/Heatseekers/PyCharm/.venv/lib/python3.12/site-packages/flask/app.py", line 1498, in __call__
    return self.wsgi_app(environ, start_response)
           ^^^^^^^^^^^^^^^^^^^^^^^^^^^^^^^^^^^^^^
  File "/home/weidi/Desktop/4BI/ITP√ú/Heatseekers/PyCharm/.venv/lib/python3.12/site-packages/flask/app.py", line 1476, in wsgi_app
    response = self.handle_exception(e)
               ^^^^^^^^^^^^^^^^^^^^^^^^
  File "/home/weidi/Desktop/4BI/ITP√ú/Heatseekers/PyCharm/.venv/lib/python3.12/site-packages/flask/app.py", line 823, in handle_exception
    server_error = self.ensure_sync(handler)(server_error)
                   ^^^^^^^^^^^^^^^^^^^^^^^^^^^^^^^^^^^^^^^
TypeError: errorhandler() takes 0 positional arguments but 1 was given
2024-11-05 16:33:30,026 - ERROR - Exception on /favicon.ico [GET]
Traceback (most recent call last):
  File "/home/weidi/Desktop/4BI/ITP√ú/Heatseekers/PyCharm/.venv/lib/python3.12/site-packages/flask/app.py", line 880, in full_dispatch_request
    rv = self.dispatch_request()
         ^^^^^^^^^^^^^^^^^^^^^^^
  File "/home/weidi/Desktop/4BI/ITP√ú/Heatseekers/PyCharm/.venv/lib/python3.12/site-packages/flask/app.py", line 854, in dispatch_request
    self.raise_routing_exception(req)
  File "/home/weidi/Desktop/4BI/ITP√ú/Heatseekers/PyCharm/.venv/lib/python3.12/site-packages/flask/app.py", line 463, in raise_routing_exception
    raise request.routing_exception  # type: ignore[misc]
    ^^^^^^^^^^^^^^^^^^^^^^^^^^^^^^^
  File "/home/weidi/Desktop/4BI/ITP√ú/Heatseekers/PyCharm/.venv/lib/python3.12/site-packages/flask/ctx.py", line 362, in match_request
    result = self.url_adapter.match(return_rule=True)  # type: ignore
             ^^^^^^^^^^^^^^^^^^^^^^^^^^^^^^^^^^^^^^^^
  File "/home/weidi/Desktop/4BI/ITP√ú/Heatseekers/PyCharm/.venv/lib/python3.12/site-packages/werkzeug/routing/map.py", line 629, in match
    raise NotFound() from None
werkzeug.exceptions.NotFound: 404 Not Found: The requested URL was not found on the server. If you entered the URL manually please check your spelling and try again.

During handling of the above exception, another exception occurred:

Traceback (most recent call last):
  File "/home/weidi/Desktop/4BI/ITP√ú/Heatseekers/PyCharm/.venv/lib/python3.12/site-packages/flask/app.py", line 1473, in wsgi_app
    response = self.full_dispatch_request()
               ^^^^^^^^^^^^^^^^^^^^^^^^^^^^
  File "/home/weidi/Desktop/4BI/ITP√ú/Heatseekers/PyCharm/.venv/lib/python3.12/site-packages/flask/app.py", line 882, in full_dispatch_request
    rv = self.handle_user_exception(e)
         ^^^^^^^^^^^^^^^^^^^^^^^^^^^^^
  File "/home/weidi/Desktop/4BI/ITP√ú/Heatseekers/PyCharm/.venv/lib/python3.12/site-packages/flask/app.py", line 765, in handle_user_exception
    return self.handle_http_exception(e)
           ^^^^^^^^^^^^^^^^^^^^^^^^^^^^^
  File "/home/weidi/Desktop/4BI/ITP√ú/Heatseekers/PyCharm/.venv/lib/python3.12/site-packages/flask/app.py", line 740, in handle_http_exception
    return self.ensure_sync(handler)(e)  # type: ignore[no-any-return]
           ^^^^^^^^^^^^^^^^^^^^^^^^^^^^
TypeError: errorhandler() takes 0 positional arguments but 1 was given
2024-11-05 16:33:30,028 - INFO - 10.0.76.44 - - [05/Nov/2024 16:33:30] "[35m[1mGET /favicon.ico HTTP/1.1[0m" 500 -
2024-11-05 16:33:30,031 - ERROR - Error on request:
Traceback (most recent call last):
  File "/home/weidi/Desktop/4BI/ITP√ú/Heatseekers/PyCharm/.venv/lib/python3.12/site-packages/flask/app.py", line 880, in full_dispatch_request
    rv = self.dispatch_request()
         ^^^^^^^^^^^^^^^^^^^^^^^
  File "/home/weidi/Desktop/4BI/ITP√ú/Heatseekers/PyCharm/.venv/lib/python3.12/site-packages/flask/app.py", line 854, in dispatch_request
    self.raise_routing_exception(req)
  File "/home/weidi/Desktop/4BI/ITP√ú/Heatseekers/PyCharm/.venv/lib/python3.12/site-packages/flask/app.py", line 463, in raise_routing_exception
    raise request.routing_exception  # type: ignore[misc]
  File "/home/weidi/Desktop/4BI/ITP√ú/Heatseekers/PyCharm/.venv/lib/python3.12/site-packages/flask/ctx.py", line 362, in match_request
    result = self.url_adapter.match(return_rule=True)  # type: ignore
             ^^^^^^^^^^^^^^^^^^^^^^^^^^^^^^^^^^^^^^^^^^^^^^^^^^^^^^^^
  File "/home/weidi/Desktop/4BI/ITP√ú/Heatseekers/PyCharm/.venv/lib/python3.12/site-packages/werkzeug/routing/map.py", line 629, in match
    raise NotFound() from None
werkzeug.exceptions.NotFound: 404 Not Found: The requested URL was not found on the server. If you entered the URL manually please check your spelling and try again.

During handling of the above exception, another exception occurred:

Traceback (most recent call last):
  File "/home/weidi/Desktop/4BI/ITP√ú/Heatseekers/PyCharm/.venv/lib/python3.12/site-packages/flask/app.py", line 1473, in wsgi_app
    response = self.full_dispatch_request()
               ^^^^^^^^^^^^^^^^^^^^^^^^^^^^
  File "/home/weidi/Desktop/4BI/ITP√ú/Heatseekers/PyCharm/.venv/lib/python3.12/site-packages/flask/app.py", line 882, in full_dispatch_request
    rv = self.handle_user_exception(e)
         ^^^^^^^^^^^^^^^^^^^^^^^^^^^^^
  File "/home/weidi/Desktop/4BI/ITP√ú/Heatseekers/PyCharm/.venv/lib/python3.12/site-packages/flask/app.py", line 765, in handle_user_exception
    return self.handle_http_exception(e)
           ^^^^^^^^^^^^^^^^^^^^^^^^^^^^^
  File "/home/weidi/Desktop/4BI/ITP√ú/Heatseekers/PyCharm/.venv/lib/python3.12/site-packages/flask/app.py", line 740, in handle_http_exception
    return self.ensure_sync(handler)(e)  # type: ignore[no-any-return]
           ^^^^^^^^^^^^^^^^^^^^^^^^^^^^^^^^^^^^^^^^^^^^^^^^^^^^^^^^^^^
TypeError: errorhandler() takes 0 positional arguments but 1 was given

During handling of the above exception, another exception occurred:

Traceback (most recent call last):
  File "/home/weidi/Desktop/4BI/ITP√ú/Heatseekers/PyCharm/.venv/lib/python3.12/site-packages/werkzeug/serving.py", line 370, in run_wsgi
    execute(self.server.app)
  File "/home/weidi/Desktop/4BI/ITP√ú/Heatseekers/PyCharm/.venv/lib/python3.12/site-packages/werkzeug/serving.py", line 331, in execute
    application_iter = app(environ, start_response)
                       ^^^^^^^^^^^^^^^^^^^^^^^^^^^^
  File "/home/weidi/Desktop/4BI/ITP√ú/Heatseekers/PyCharm/.venv/lib/python3.12/site-packages/flask/app.py", line 1498, in __call__
    return self.wsgi_app(environ, start_response)
           ^^^^^^^^^^^^^^^^^^^^^^^^^^^^^^^^^^^^^^
  File "/home/weidi/Desktop/4BI/ITP√ú/Heatseekers/PyCharm/.venv/lib/python3.12/site-packages/flask/app.py", line 1476, in wsgi_app
    response = self.handle_exception(e)
               ^^^^^^^^^^^^^^^^^^^^^^^^
  File "/home/weidi/Desktop/4BI/ITP√ú/Heatseekers/PyCharm/.venv/lib/python3.12/site-packages/flask/app.py", line 823, in handle_exception
    server_error = self.ensure_sync(handler)(server_error)
                   ^^^^^^^^^^^^^^^^^^^^^^^^^^^^^^^^^^^^^^^
TypeError: errorhandler() takes 0 positional arguments but 1 was given
2024-11-05 16:33:49,458 - ERROR - Exception on /view [POST]
Traceback (most recent call last):
  File "/home/weidi/Desktop/4BI/ITP√ú/Heatseekers/PyCharm/.venv/lib/python3.12/site-packages/flask/app.py", line 880, in full_dispatch_request
    rv = self.dispatch_request()
         ^^^^^^^^^^^^^^^^^^^^^^^
  File "/home/weidi/Desktop/4BI/ITP√ú/Heatseekers/PyCharm/.venv/lib/python3.12/site-packages/flask/app.py", line 865, in dispatch_request
    return self.ensure_sync(self.view_functions[rule.endpoint])(**view_args)  # type: ignore[no-any-return]
           ^^^^^^^^^^^^^^^^^^^^^^^^^^^^^^^^^^^^^^^^^^^^^^^^^^^^^^^^^^^^^^^^^
  File "/home/weidi/Desktop/4BI/ITP√ú/Heatseekers/github/server.py", line 39, in view
    print(tmp['isadmin'])
          ~~~^^^^^^^^^^^
KeyError: 'isadmin'

During handling of the above exception, another exception occurred:

Traceback (most recent call last):
  File "/home/weidi/Desktop/4BI/ITP√ú/Heatseekers/PyCharm/.venv/lib/python3.12/site-packages/flask/app.py", line 1473, in wsgi_app
    response = self.full_dispatch_request()
               ^^^^^^^^^^^^^^^^^^^^^^^^^^^^
  File "/home/weidi/Desktop/4BI/ITP√ú/Heatseekers/PyCharm/.venv/lib/python3.12/site-packages/flask/app.py", line 882, in full_dispatch_request
    rv = self.handle_user_exception(e)
         ^^^^^^^^^^^^^^^^^^^^^^^^^^^^^
  File "/home/weidi/Desktop/4BI/ITP√ú/Heatseekers/PyCharm/.venv/lib/python3.12/site-packages/flask/app.py", line 772, in handle_user_exception
    return self.ensure_sync(handler)(e)  # type: ignore[no-any-return]
           ^^^^^^^^^^^^^^^^^^^^^^^^^^^^
TypeError: errorhandler() takes 0 positional arguments but 1 was given
2024-11-05 16:33:49,459 - INFO - 10.0.76.44 - - [05/Nov/2024 16:33:49] "[35m[1mPOST /view HTTP/1.1[0m" 500 -
2024-11-05 16:33:49,463 - ERROR - Error on request:
Traceback (most recent call last):
  File "/home/weidi/Desktop/4BI/ITP√ú/Heatseekers/PyCharm/.venv/lib/python3.12/site-packages/flask/app.py", line 880, in full_dispatch_request
    rv = self.dispatch_request()
         ^^^^^^^^^^^^^^^^^^^^^^^
  File "/home/weidi/Desktop/4BI/ITP√ú/Heatseekers/PyCharm/.venv/lib/python3.12/site-packages/flask/app.py", line 865, in dispatch_request
    return self.ensure_sync(self.view_functions[rule.endpoint])(**view_args)  # type: ignore[no-any-return]
           ^^^^^^^^^^^^^^^^^^^^^^^^^^^^^^^^^^^^^^^^^^^^^^^^^^^^^^^^^^^^^^^^^^^^^^^^^^^^^^^^^^^^^^^^^^^^^^^^
  File "/home/weidi/Desktop/4BI/ITP√ú/Heatseekers/github/server.py", line 39, in view
    print(tmp['isadmin'])
          ^^^^^^^^^^^^^^^
KeyError: 'isadmin'

During handling of the above exception, another exception occurred:

Traceback (most recent call last):
  File "/home/weidi/Desktop/4BI/ITP√ú/Heatseekers/PyCharm/.venv/lib/python3.12/site-packages/flask/app.py", line 1473, in wsgi_app
    response = self.full_dispatch_request()
               ^^^^^^^^^^^^^^^^^^^^^^^^^^^^
  File "/home/weidi/Desktop/4BI/ITP√ú/Heatseekers/PyCharm/.venv/lib/python3.12/site-packages/flask/app.py", line 882, in full_dispatch_request
    rv = self.handle_user_exception(e)
         ^^^^^^^^^^^^^^^^^^^^^^^^^^^^^
  File "/home/weidi/Desktop/4BI/ITP√ú/Heatseekers/PyCharm/.venv/lib/python3.12/site-packages/flask/app.py", line 772, in handle_user_exception
    return self.ensure_sync(handler)(e)  # type: ignore[no-any-return]
           ^^^^^^^^^^^^^^^^^^^^^^^^^^^^^^^^^^^^^^^^^^^^^^^^^^^^^^^^^^^
TypeError: errorhandler() takes 0 positional arguments but 1 was given

During handling of the above exception, another exception occurred:

Traceback (most recent call last):
  File "/home/weidi/Desktop/4BI/ITP√ú/Heatseekers/PyCharm/.venv/lib/python3.12/site-packages/werkzeug/serving.py", line 370, in run_wsgi
    execute(self.server.app)
  File "/home/weidi/Desktop/4BI/ITP√ú/Heatseekers/PyCharm/.venv/lib/python3.12/site-packages/werkzeug/serving.py", line 331, in execute
    application_iter = app(environ, start_response)
                       ^^^^^^^^^^^^^^^^^^^^^^^^^^^^
  File "/home/weidi/Desktop/4BI/ITP√ú/Heatseekers/PyCharm/.venv/lib/python3.12/site-packages/flask/app.py", line 1498, in __call__
    return self.wsgi_app(environ, start_response)
           ^^^^^^^^^^^^^^^^^^^^^^^^^^^^^^^^^^^^^^
  File "/home/weidi/Desktop/4BI/ITP√ú/Heatseekers/PyCharm/.venv/lib/python3.12/site-packages/flask/app.py", line 1476, in wsgi_app
    response = self.handle_exception(e)
               ^^^^^^^^^^^^^^^^^^^^^^^^
  File "/home/weidi/Desktop/4BI/ITP√ú/Heatseekers/PyCharm/.venv/lib/python3.12/site-packages/flask/app.py", line 823, in handle_exception
    server_error = self.ensure_sync(handler)(server_error)
                   ^^^^^^^^^^^^^^^^^^^^^^^^^^^^^^^^^^^^^^^
TypeError: errorhandler() takes 0 positional arguments but 1 was given
2024-11-05 16:33:49,564 - ERROR - Exception on /favicon.ico [GET]
Traceback (most recent call last):
  File "/home/weidi/Desktop/4BI/ITP√ú/Heatseekers/PyCharm/.venv/lib/python3.12/site-packages/flask/app.py", line 880, in full_dispatch_request
    rv = self.dispatch_request()
         ^^^^^^^^^^^^^^^^^^^^^^^
  File "/home/weidi/Desktop/4BI/ITP√ú/Heatseekers/PyCharm/.venv/lib/python3.12/site-packages/flask/app.py", line 854, in dispatch_request
    self.raise_routing_exception(req)
  File "/home/weidi/Desktop/4BI/ITP√ú/Heatseekers/PyCharm/.venv/lib/python3.12/site-packages/flask/app.py", line 463, in raise_routing_exception
    raise request.routing_exception  # type: ignore[misc]
    ^^^^^^^^^^^^^^^^^^^^^^^^^^^^^^^
  File "/home/weidi/Desktop/4BI/ITP√ú/Heatseekers/PyCharm/.venv/lib/python3.12/site-packages/flask/ctx.py", line 362, in match_request
    result = self.url_adapter.match(return_rule=True)  # type: ignore
             ^^^^^^^^^^^^^^^^^^^^^^^^^^^^^^^^^^^^^^^^
  File "/home/weidi/Desktop/4BI/ITP√ú/Heatseekers/PyCharm/.venv/lib/python3.12/site-packages/werkzeug/routing/map.py", line 629, in match
    raise NotFound() from None
werkzeug.exceptions.NotFound: 404 Not Found: The requested URL was not found on the server. If you entered the URL manually please check your spelling and try again.

During handling of the above exception, another exception occurred:

Traceback (most recent call last):
  File "/home/weidi/Desktop/4BI/ITP√ú/Heatseekers/PyCharm/.venv/lib/python3.12/site-packages/flask/app.py", line 1473, in wsgi_app
    response = self.full_dispatch_request()
               ^^^^^^^^^^^^^^^^^^^^^^^^^^^^
  File "/home/weidi/Desktop/4BI/ITP√ú/Heatseekers/PyCharm/.venv/lib/python3.12/site-packages/flask/app.py", line 882, in full_dispatch_request
    rv = self.handle_user_exception(e)
         ^^^^^^^^^^^^^^^^^^^^^^^^^^^^^
  File "/home/weidi/Desktop/4BI/ITP√ú/Heatseekers/PyCharm/.venv/lib/python3.12/site-packages/flask/app.py", line 765, in handle_user_exception
    return self.handle_http_exception(e)
           ^^^^^^^^^^^^^^^^^^^^^^^^^^^^^
  File "/home/weidi/Desktop/4BI/ITP√ú/Heatseekers/PyCharm/.venv/lib/python3.12/site-packages/flask/app.py", line 740, in handle_http_exception
    return self.ensure_sync(handler)(e)  # type: ignore[no-any-return]
           ^^^^^^^^^^^^^^^^^^^^^^^^^^^^
TypeError: errorhandler() takes 0 positional arguments but 1 was given
2024-11-05 16:33:49,566 - INFO - 10.0.76.44 - - [05/Nov/2024 16:33:49] "[35m[1mGET /favicon.ico HTTP/1.1[0m" 500 -
2024-11-05 16:33:49,570 - ERROR - Error on request:
Traceback (most recent call last):
  File "/home/weidi/Desktop/4BI/ITP√ú/Heatseekers/PyCharm/.venv/lib/python3.12/site-packages/flask/app.py", line 880, in full_dispatch_request
    rv = self.dispatch_request()
         ^^^^^^^^^^^^^^^^^^^^^^^
  File "/home/weidi/Desktop/4BI/ITP√ú/Heatseekers/PyCharm/.venv/lib/python3.12/site-packages/flask/app.py", line 854, in dispatch_request
    self.raise_routing_exception(req)
  File "/home/weidi/Desktop/4BI/ITP√ú/Heatseekers/PyCharm/.venv/lib/python3.12/site-packages/flask/app.py", line 463, in raise_routing_exception
    raise request.routing_exception  # type: ignore[misc]
  File "/home/weidi/Desktop/4BI/ITP√ú/Heatseekers/PyCharm/.venv/lib/python3.12/site-packages/flask/ctx.py", line 362, in match_request
    result = self.url_adapter.match(return_rule=True)  # type: ignore
             ^^^^^^^^^^^^^^^^^^^^^^^^^^^^^^^^^^^^^^^^^^^^^^^^^^^^^^^^
  File "/home/weidi/Desktop/4BI/ITP√ú/Heatseekers/PyCharm/.venv/lib/python3.12/site-packages/werkzeug/routing/map.py", line 629, in match
    raise NotFound() from None
werkzeug.exceptions.NotFound: 404 Not Found: The requested URL was not found on the server. If you entered the URL manually please check your spelling and try again.

During handling of the above exception, another exception occurred:

Traceback (most recent call last):
  File "/home/weidi/Desktop/4BI/ITP√ú/Heatseekers/PyCharm/.venv/lib/python3.12/site-packages/flask/app.py", line 1473, in wsgi_app
    response = self.full_dispatch_request()
               ^^^^^^^^^^^^^^^^^^^^^^^^^^^^
  File "/home/weidi/Desktop/4BI/ITP√ú/Heatseekers/PyCharm/.venv/lib/python3.12/site-packages/flask/app.py", line 882, in full_dispatch_request
    rv = self.handle_user_exception(e)
         ^^^^^^^^^^^^^^^^^^^^^^^^^^^^^
  File "/home/weidi/Desktop/4BI/ITP√ú/Heatseekers/PyCharm/.venv/lib/python3.12/site-packages/flask/app.py", line 765, in handle_user_exception
    return self.handle_http_exception(e)
           ^^^^^^^^^^^^^^^^^^^^^^^^^^^^^
  File "/home/weidi/Desktop/4BI/ITP√ú/Heatseekers/PyCharm/.venv/lib/python3.12/site-packages/flask/app.py", line 740, in handle_http_exception
    return self.ensure_sync(handler)(e)  # type: ignore[no-any-return]
           ^^^^^^^^^^^^^^^^^^^^^^^^^^^^^^^^^^^^^^^^^^^^^^^^^^^^^^^^^^^
TypeError: errorhandler() takes 0 positional arguments but 1 was given

During handling of the above exception, another exception occurred:

Traceback (most recent call last):
  File "/home/weidi/Desktop/4BI/ITP√ú/Heatseekers/PyCharm/.venv/lib/python3.12/site-packages/werkzeug/serving.py", line 370, in run_wsgi
    execute(self.server.app)
  File "/home/weidi/Desktop/4BI/ITP√ú/Heatseekers/PyCharm/.venv/lib/python3.12/site-packages/werkzeug/serving.py", line 331, in execute
    application_iter = app(environ, start_response)
                       ^^^^^^^^^^^^^^^^^^^^^^^^^^^^
  File "/home/weidi/Desktop/4BI/ITP√ú/Heatseekers/PyCharm/.venv/lib/python3.12/site-packages/flask/app.py", line 1498, in __call__
    return self.wsgi_app(environ, start_response)
           ^^^^^^^^^^^^^^^^^^^^^^^^^^^^^^^^^^^^^^
  File "/home/weidi/Desktop/4BI/ITP√ú/Heatseekers/PyCharm/.venv/lib/python3.12/site-packages/flask/app.py", line 1476, in wsgi_app
    response = self.handle_exception(e)
               ^^^^^^^^^^^^^^^^^^^^^^^^
  File "/home/weidi/Desktop/4BI/ITP√ú/Heatseekers/PyCharm/.venv/lib/python3.12/site-packages/flask/app.py", line 823, in handle_exception
    server_error = self.ensure_sync(handler)(server_error)
                   ^^^^^^^^^^^^^^^^^^^^^^^^^^^^^^^^^^^^^^^
TypeError: errorhandler() takes 0 positional arguments but 1 was given
2024-11-05 16:33:50,621 - INFO - 10.0.76.44 - - [05/Nov/2024 16:33:50] "[36mGET /static/icon.png HTTP/1.1[0m" 304 -
2024-11-05 16:33:51,471 - INFO - Login page accessed
2024-11-05 16:33:51,474 - INFO - 10.0.76.44 - - [05/Nov/2024 16:33:51] "GET / HTTP/1.1" 200 -
2024-11-05 16:33:51,518 - INFO - 10.0.76.44 - - [05/Nov/2024 16:33:51] "[36mGET /static/LoginPage.css HTTP/1.1[0m" 304 -
2024-11-05 16:33:51,628 - INFO - 10.0.76.44 - - [05/Nov/2024 16:33:51] "[36mGET /static/icon.png HTTP/1.1[0m" 304 -
2024-11-05 16:33:53,914 - ERROR - Exception on /view [POST]
Traceback (most recent call last):
  File "/home/weidi/Desktop/4BI/ITP√ú/Heatseekers/PyCharm/.venv/lib/python3.12/site-packages/flask/app.py", line 880, in full_dispatch_request
    rv = self.dispatch_request()
         ^^^^^^^^^^^^^^^^^^^^^^^
  File "/home/weidi/Desktop/4BI/ITP√ú/Heatseekers/PyCharm/.venv/lib/python3.12/site-packages/flask/app.py", line 865, in dispatch_request
    return self.ensure_sync(self.view_functions[rule.endpoint])(**view_args)  # type: ignore[no-any-return]
           ^^^^^^^^^^^^^^^^^^^^^^^^^^^^^^^^^^^^^^^^^^^^^^^^^^^^^^^^^^^^^^^^^
  File "/home/weidi/Desktop/4BI/ITP√ú/Heatseekers/github/server.py", line 39, in view
    print(tmp['isadmin'])
          ~~~^^^^^^^^^^^
KeyError: 'isadmin'

During handling of the above exception, another exception occurred:

Traceback (most recent call last):
  File "/home/weidi/Desktop/4BI/ITP√ú/Heatseekers/PyCharm/.venv/lib/python3.12/site-packages/flask/app.py", line 1473, in wsgi_app
    response = self.full_dispatch_request()
               ^^^^^^^^^^^^^^^^^^^^^^^^^^^^
  File "/home/weidi/Desktop/4BI/ITP√ú/Heatseekers/PyCharm/.venv/lib/python3.12/site-packages/flask/app.py", line 882, in full_dispatch_request
    rv = self.handle_user_exception(e)
         ^^^^^^^^^^^^^^^^^^^^^^^^^^^^^
  File "/home/weidi/Desktop/4BI/ITP√ú/Heatseekers/PyCharm/.venv/lib/python3.12/site-packages/flask/app.py", line 772, in handle_user_exception
    return self.ensure_sync(handler)(e)  # type: ignore[no-any-return]
           ^^^^^^^^^^^^^^^^^^^^^^^^^^^^
TypeError: errorhandler() takes 0 positional arguments but 1 was given
2024-11-05 16:33:53,915 - INFO - 10.0.76.44 - - [05/Nov/2024 16:33:53] "[35m[1mPOST /view HTTP/1.1[0m" 500 -
2024-11-05 16:33:53,917 - ERROR - Error on request:
Traceback (most recent call last):
  File "/home/weidi/Desktop/4BI/ITP√ú/Heatseekers/PyCharm/.venv/lib/python3.12/site-packages/flask/app.py", line 880, in full_dispatch_request
    rv = self.dispatch_request()
         ^^^^^^^^^^^^^^^^^^^^^^^
  File "/home/weidi/Desktop/4BI/ITP√ú/Heatseekers/PyCharm/.venv/lib/python3.12/site-packages/flask/app.py", line 865, in dispatch_request
    return self.ensure_sync(self.view_functions[rule.endpoint])(**view_args)  # type: ignore[no-any-return]
           ^^^^^^^^^^^^^^^^^^^^^^^^^^^^^^^^^^^^^^^^^^^^^^^^^^^^^^^^^^^^^^^^^^^^^^^^^^^^^^^^^^^^^^^^^^^^^^^^
  File "/home/weidi/Desktop/4BI/ITP√ú/Heatseekers/github/server.py", line 39, in view
    print(tmp['isadmin'])
          ^^^^^^^^^^^^^^^
KeyError: 'isadmin'

During handling of the above exception, another exception occurred:

Traceback (most recent call last):
  File "/home/weidi/Desktop/4BI/ITP√ú/Heatseekers/PyCharm/.venv/lib/python3.12/site-packages/flask/app.py", line 1473, in wsgi_app
    response = self.full_dispatch_request()
               ^^^^^^^^^^^^^^^^^^^^^^^^^^^^
  File "/home/weidi/Desktop/4BI/ITP√ú/Heatseekers/PyCharm/.venv/lib/python3.12/site-packages/flask/app.py", line 882, in full_dispatch_request
    rv = self.handle_user_exception(e)
         ^^^^^^^^^^^^^^^^^^^^^^^^^^^^^
  File "/home/weidi/Desktop/4BI/ITP√ú/Heatseekers/PyCharm/.venv/lib/python3.12/site-packages/flask/app.py", line 772, in handle_user_exception
    return self.ensure_sync(handler)(e)  # type: ignore[no-any-return]
           ^^^^^^^^^^^^^^^^^^^^^^^^^^^^^^^^^^^^^^^^^^^^^^^^^^^^^^^^^^^
TypeError: errorhandler() takes 0 positional arguments but 1 was given

During handling of the above exception, another exception occurred:

Traceback (most recent call last):
  File "/home/weidi/Desktop/4BI/ITP√ú/Heatseekers/PyCharm/.venv/lib/python3.12/site-packages/werkzeug/serving.py", line 370, in run_wsgi
    execute(self.server.app)
  File "/home/weidi/Desktop/4BI/ITP√ú/Heatseekers/PyCharm/.venv/lib/python3.12/site-packages/werkzeug/serving.py", line 331, in execute
    application_iter = app(environ, start_response)
                       ^^^^^^^^^^^^^^^^^^^^^^^^^^^^
  File "/home/weidi/Desktop/4BI/ITP√ú/Heatseekers/PyCharm/.venv/lib/python3.12/site-packages/flask/app.py", line 1498, in __call__
    return self.wsgi_app(environ, start_response)
           ^^^^^^^^^^^^^^^^^^^^^^^^^^^^^^^^^^^^^^
  File "/home/weidi/Desktop/4BI/ITP√ú/Heatseekers/PyCharm/.venv/lib/python3.12/site-packages/flask/app.py", line 1476, in wsgi_app
    response = self.handle_exception(e)
               ^^^^^^^^^^^^^^^^^^^^^^^^
  File "/home/weidi/Desktop/4BI/ITP√ú/Heatseekers/PyCharm/.venv/lib/python3.12/site-packages/flask/app.py", line 823, in handle_exception
    server_error = self.ensure_sync(handler)(server_error)
                   ^^^^^^^^^^^^^^^^^^^^^^^^^^^^^^^^^^^^^^^
TypeError: errorhandler() takes 0 positional arguments but 1 was given
2024-11-05 16:33:54,060 - ERROR - Exception on /favicon.ico [GET]
Traceback (most recent call last):
  File "/home/weidi/Desktop/4BI/ITP√ú/Heatseekers/PyCharm/.venv/lib/python3.12/site-packages/flask/app.py", line 880, in full_dispatch_request
    rv = self.dispatch_request()
         ^^^^^^^^^^^^^^^^^^^^^^^
  File "/home/weidi/Desktop/4BI/ITP√ú/Heatseekers/PyCharm/.venv/lib/python3.12/site-packages/flask/app.py", line 854, in dispatch_request
    self.raise_routing_exception(req)
  File "/home/weidi/Desktop/4BI/ITP√ú/Heatseekers/PyCharm/.venv/lib/python3.12/site-packages/flask/app.py", line 463, in raise_routing_exception
    raise request.routing_exception  # type: ignore[misc]
    ^^^^^^^^^^^^^^^^^^^^^^^^^^^^^^^
  File "/home/weidi/Desktop/4BI/ITP√ú/Heatseekers/PyCharm/.venv/lib/python3.12/site-packages/flask/ctx.py", line 362, in match_request
    result = self.url_adapter.match(return_rule=True)  # type: ignore
             ^^^^^^^^^^^^^^^^^^^^^^^^^^^^^^^^^^^^^^^^
  File "/home/weidi/Desktop/4BI/ITP√ú/Heatseekers/PyCharm/.venv/lib/python3.12/site-packages/werkzeug/routing/map.py", line 629, in match
    raise NotFound() from None
werkzeug.exceptions.NotFound: 404 Not Found: The requested URL was not found on the server. If you entered the URL manually please check your spelling and try again.

During handling of the above exception, another exception occurred:

Traceback (most recent call last):
  File "/home/weidi/Desktop/4BI/ITP√ú/Heatseekers/PyCharm/.venv/lib/python3.12/site-packages/flask/app.py", line 1473, in wsgi_app
    response = self.full_dispatch_request()
               ^^^^^^^^^^^^^^^^^^^^^^^^^^^^
  File "/home/weidi/Desktop/4BI/ITP√ú/Heatseekers/PyCharm/.venv/lib/python3.12/site-packages/flask/app.py", line 882, in full_dispatch_request
    rv = self.handle_user_exception(e)
         ^^^^^^^^^^^^^^^^^^^^^^^^^^^^^
  File "/home/weidi/Desktop/4BI/ITP√ú/Heatseekers/PyCharm/.venv/lib/python3.12/site-packages/flask/app.py", line 765, in handle_user_exception
    return self.handle_http_exception(e)
           ^^^^^^^^^^^^^^^^^^^^^^^^^^^^^
  File "/home/weidi/Desktop/4BI/ITP√ú/Heatseekers/PyCharm/.venv/lib/python3.12/site-packages/flask/app.py", line 740, in handle_http_exception
    return self.ensure_sync(handler)(e)  # type: ignore[no-any-return]
           ^^^^^^^^^^^^^^^^^^^^^^^^^^^^
TypeError: errorhandler() takes 0 positional arguments but 1 was given
2024-11-05 16:33:54,061 - INFO - 10.0.76.44 - - [05/Nov/2024 16:33:54] "[35m[1mGET /favicon.ico HTTP/1.1[0m" 500 -
2024-11-05 16:33:54,064 - ERROR - Error on request:
Traceback (most recent call last):
  File "/home/weidi/Desktop/4BI/ITP√ú/Heatseekers/PyCharm/.venv/lib/python3.12/site-packages/flask/app.py", line 880, in full_dispatch_request
    rv = self.dispatch_request()
         ^^^^^^^^^^^^^^^^^^^^^^^
  File "/home/weidi/Desktop/4BI/ITP√ú/Heatseekers/PyCharm/.venv/lib/python3.12/site-packages/flask/app.py", line 854, in dispatch_request
    self.raise_routing_exception(req)
  File "/home/weidi/Desktop/4BI/ITP√ú/Heatseekers/PyCharm/.venv/lib/python3.12/site-packages/flask/app.py", line 463, in raise_routing_exception
    raise request.routing_exception  # type: ignore[misc]
  File "/home/weidi/Desktop/4BI/ITP√ú/Heatseekers/PyCharm/.venv/lib/python3.12/site-packages/flask/ctx.py", line 362, in match_request
    result = self.url_adapter.match(return_rule=True)  # type: ignore
             ^^^^^^^^^^^^^^^^^^^^^^^^^^^^^^^^^^^^^^^^^^^^^^^^^^^^^^^^
  File "/home/weidi/Desktop/4BI/ITP√ú/Heatseekers/PyCharm/.venv/lib/python3.12/site-packages/werkzeug/routing/map.py", line 629, in match
    raise NotFound() from None
werkzeug.exceptions.NotFound: 404 Not Found: The requested URL was not found on the server. If you entered the URL manually please check your spelling and try again.

During handling of the above exception, another exception occurred:

Traceback (most recent call last):
  File "/home/weidi/Desktop/4BI/ITP√ú/Heatseekers/PyCharm/.venv/lib/python3.12/site-packages/flask/app.py", line 1473, in wsgi_app
    response = self.full_dispatch_request()
               ^^^^^^^^^^^^^^^^^^^^^^^^^^^^
  File "/home/weidi/Desktop/4BI/ITP√ú/Heatseekers/PyCharm/.venv/lib/python3.12/site-packages/flask/app.py", line 882, in full_dispatch_request
    rv = self.handle_user_exception(e)
         ^^^^^^^^^^^^^^^^^^^^^^^^^^^^^
  File "/home/weidi/Desktop/4BI/ITP√ú/Heatseekers/PyCharm/.venv/lib/python3.12/site-packages/flask/app.py", line 765, in handle_user_exception
    return self.handle_http_exception(e)
           ^^^^^^^^^^^^^^^^^^^^^^^^^^^^^
  File "/home/weidi/Desktop/4BI/ITP√ú/Heatseekers/PyCharm/.venv/lib/python3.12/site-packages/flask/app.py", line 740, in handle_http_exception
    return self.ensure_sync(handler)(e)  # type: ignore[no-any-return]
           ^^^^^^^^^^^^^^^^^^^^^^^^^^^^^^^^^^^^^^^^^^^^^^^^^^^^^^^^^^^
TypeError: errorhandler() takes 0 positional arguments but 1 was given

During handling of the above exception, another exception occurred:

Traceback (most recent call last):
  File "/home/weidi/Desktop/4BI/ITP√ú/Heatseekers/PyCharm/.venv/lib/python3.12/site-packages/werkzeug/serving.py", line 370, in run_wsgi
    execute(self.server.app)
  File "/home/weidi/Desktop/4BI/ITP√ú/Heatseekers/PyCharm/.venv/lib/python3.12/site-packages/werkzeug/serving.py", line 331, in execute
    application_iter = app(environ, start_response)
                       ^^^^^^^^^^^^^^^^^^^^^^^^^^^^
  File "/home/weidi/Desktop/4BI/ITP√ú/Heatseekers/PyCharm/.venv/lib/python3.12/site-packages/flask/app.py", line 1498, in __call__
    return self.wsgi_app(environ, start_response)
           ^^^^^^^^^^^^^^^^^^^^^^^^^^^^^^^^^^^^^^
  File "/home/weidi/Desktop/4BI/ITP√ú/Heatseekers/PyCharm/.venv/lib/python3.12/site-packages/flask/app.py", line 1476, in wsgi_app
    response = self.handle_exception(e)
               ^^^^^^^^^^^^^^^^^^^^^^^^
  File "/home/weidi/Desktop/4BI/ITP√ú/Heatseekers/PyCharm/.venv/lib/python3.12/site-packages/flask/app.py", line 823, in handle_exception
    server_error = self.ensure_sync(handler)(server_error)
                   ^^^^^^^^^^^^^^^^^^^^^^^^^^^^^^^^^^^^^^^
TypeError: errorhandler() takes 0 positional arguments but 1 was given
